Workbook
Name MaxLevel: LevelFormula!$B$20

Sheet ReadMe
A1: Minion data
A3: Values here are placeholders to show the format, not balance suggestions.
A4: In Unity: Sunder > Import Minion Data reads this file (save it first) and creates/updates every minion, ability and faction roster. The Console lists any problems by sheet and row.
A5: Rows on a _Data sheet with no Display Name are skipped, so placeholder rows are fine.
A6: The Worker row (W) is the faction's imp. Imps read Health (max health), Strength (dig damage per second) and SkillBuild (claim/reinforce speed, 1 = normal) at their level; any of these left off the _Levels sheet keeps the imp prefab's own value.
A7: Header cells have comments (hover) explaining each column.
A9: Sheets
A10: Stats – master list of levelled stats: default value and whether it is a whole number. Adding a stat starts here.
A11: DamageTypes – master list of damage types. Column names in *_Data sheets (Dmg_<ID>) must match these IDs.
A12: Abilities – one row per ability. Minion AbilityN columns hold an AbilityID from here.
A13: 01U_Data – revised per-minion columns: Movement, per-damage-type multipliers, summon prerequisites.
A14: 01U_Levels – per-stat Min (level 1), Max (level 10), Curve and Skew. Grey L1–L10 columns are a live preview only; the game ignores them.
... A23: • Sheets are found by suffix (_Data, _Levels, _Relations) so per-faction pairs work fine.

Sheet Stats
A1: StatID | B1: Description | C1: Default | D1: WholeNumber
A2: Experience | B2: Total experience needed to be this level | C2: 0 | D2: TRUE
A3: Salary | B3: Gold cost to sustain this unit each payday | C3: 0 | D3: TRUE
A4: Health | B4: Total health of minion | C4: 1 | D4: TRUE
A5: Strength | B5: Damage done with physical effects | C5: 0 | D5: TRUE
A6: Accuracy | B6: Chance for attack to land on enemy | C6: 0 | D6: FALSE
A7: Dexterity | B7: Chance to dodge an attack | C7: 0 | D7: FALSE
A8: Fortitude | B8: Lessens damage from physical effects (melee and ranged) | C8: 0 | D8: TRUE
A9: Speed | B9: Movement and attack speed | C9: 1 | D9: FALSE
A10: Magic | B10: Damage done with magical effects | C10: 0 | D10: TRUE
A11: Resistance | B11: Lessens damage from magical effects (melee and ranged) | C11: 0 | D11: TRUE
A12: Luck | B12: Modifies all things a small amount | C12: 0 | D12: FALSE
A13: Weight | B13: Minion weight | C13: 0 | D13: FALSE
... A20: Anger | B20: Likelihood of getting angry | C20: 0 | D20: FALSE

Sheet LevelFormula
A1: Level stat formula
A3: t = (Level − 1) / (MaxLevel − 1) progress from 0 at level 1 to 1 at MaxLevel
A4: shaped = t ^ (2 ^ Curve) Curve bends the line; the ends stay fixed
A5: Value = Min + (Max − Min) × (1 + Skew) × shaped
A7: Curve (blank = 0)
A8: 0 → straight line: equal gain every level.
A9: > 0 → back-loaded: small gains early, big gains late. Curve 1 = t², Curve 2 = t⁴.
A10: < 0 → front-loaded: big gains early, levelling off late. Curve −1 = √t, Curve −2 = t^0.25.
A11: Level 1 is always Min and level 10 is always Max (before Skew), whatever the Curve.
A13: Skew (blank = 0)
A14: Scales the whole growth (Max − Min) without touching the level-1 value, i.e. it adjusts the slope.
A15: 0 → reaches Max exactly. 0.1 → 10% more growth (level 10 = Min + 1.1 × (Max − Min)). −0.2 → 20% less growth.
... A18: Rounding: stats marked WholeNumber on the Stats sheet are rounded, both in game and in the _Levels preview columns. The calculator below is unrounded.
A20: MaxLevel | B20: 10
A22: Calculator – edit the yellow cells
A23: Min (level 1) | B23: 100
A24: Max (level 10) | B24: 500
A25: Curve | B25: 1
A26: Skew | B26: 0
A28: Level | B28: 1 | C28: 2 | D28: 3 | E28: 4 | F28: 5 | G28: 6 | H28: 7 | I28: 8 | J28: 9 | K28: 10
A29: Linear (Curve 0, Skew 0) | B29: =$B$23+($B$24-$B$23)*((B28-1)/(MaxLevel-1)) | C29: =$B$23+($B$24-$B$23)*((C28-1)/(MaxLevel-1)) | D29: =$B$23+($B$24-$B$23)*((D28-1)/(MaxLevel-1)) | E29: =$B$23+($B$24-$B$23)*((E28-1)/(MaxLevel-1)) | F29: =$B$23+($B$24-$B$23)*((F28-1)/(MaxLevel-1)) | G29: =$B$23+($B$24-$B$23)*((G28-1)/(MaxLevel-1)) | H29: =$B$23+($B$24-$B$23)*((H28-1)/(MaxLevel-1)) | I29: =$B$23+($B$24-$B$23)*((I28-1)/(MaxLevel-1)) | ... K29: =$B$23+($B$24-$B$23)*((K28-1)/(MaxLevel-1))
A30: Result | B30: =$B$23+($B$24-$B$23)*(1+$B$26)*((B28-1)/(MaxLevel-1))^(2^$B$25) | C30: =$B$23+($B$24-$B$23)*(1+$B$26)*((C28-1)/(MaxLevel-1))^(2^$B$25) | D30: =$B$23+($B$24-$B$23)*(1+$B$26)*((D28-1)/(MaxLevel-1))^(2^$B$25) | E30: =$B$23+($B$24-$B$23)*(1+$B$26)*((E28-1)/(MaxLevel-1))^(2^$B$25) | F30: =$B$23+($B$24-$B$23)*(1+$B$26)*((F28-1)/(MaxLevel-1))^(2^$B$25) | G30: =$B$23+($B$24-$B$23)*(1+$B$26)*((G28-1)/(MaxLevel-1))^(2^$B$25) | H30: =$B$23+($B$24-$B$23)*(1+$B$26)*((H28-1)/(MaxLevel-1))^(2^$B$25) | I30: =$B$23+($B$24-$B$23)*(1+$B$26)*((I28-1)/(MaxLevel-1))^(2^$B$25) | ... K30: =$B$23+($B$24-$B$23)*(1+$B$26)*((K28-1)/(MaxLevel-1))^(2^$B$25)
A48: Curve shapes (fraction of growth reached, Skew 0)
A49: Curve \ Level | B49: 1 | C49: 2 | D49: 3 | E49: 4 | F49: 5 | G49: 6 | H49: 7 | I49: 8 | J49: 9 | K49: 10
A50: -2 | B50: =((B49-1)/(MaxLevel-1))^(2^$A50) | C50: =((C49-1)/(MaxLevel-1))^(2^$A50) | D50: =((D49-1)/(MaxLevel-1))^(2^$A50) | E50: =((E49-1)/(MaxLevel-1))^(2^$A50) | F50: =((F49-1)/(MaxLevel-1))^(2^$A50) | G50: =((G49-1)/(MaxLevel-1))^(2^$A50) | H50: =((H49-1)/(MaxLevel-1))^(2^$A50) | I50: =((I49-1)/(MaxLevel-1))^(2^$A50) | ... K50: =((K49-1)/(MaxLevel-1))^(2^$A50)
A51: -1 | B51: =((B49-1)/(MaxLevel-1))^(2^$A51) | C51: =((C49-1)/(MaxLevel-1))^(2^$A51) | D51: =((D49-1)/(MaxLevel-1))^(2^$A51) | E51: =((E49-1)/(MaxLevel-1))^(2^$A51) | F51: =((F49-1)/(MaxLevel-1))^(2^$A51) | G51: =((G49-1)/(MaxLevel-1))^(2^$A51) | H51: =((H49-1)/(MaxLevel-1))^(2^$A51) | I51: =((I49-1)/(MaxLevel-1))^(2^$A51) | ... K51: =((K49-1)/(MaxLevel-1))^(2^$A51)
A52: -0.5 | B52: =((B49-1)/(MaxLevel-1))^(2^$A52) | C52: =((C49-1)/(MaxLevel-1))^(2^$A52) | D52: =((D49-1)/(MaxLevel-1))^(2^$A52) | E52: =((E49-1)/(MaxLevel-1))^(2^$A52) | F52: =((F49-1)/(MaxLevel-1))^(2^$A52) | G52: =((G49-1)/(MaxLevel-1))^(2^$A52) | H52: =((H49-1)/(MaxLevel-1))^(2^$A52) | I52: =((I49-1)/(MaxLevel-1))^(2^$A52) | ... K52: =((K49-1)/(MaxLevel-1))^(2^$A52)
A53: 0 | B53: =((B49-1)/(MaxLevel-1))^(2^$A53) | C53: =((C49-1)/(MaxLevel-1))^(2^$A53) | D53: =((D49-1)/(MaxLevel-1))^(2^$A53) | E53: =((E49-1)/(MaxLevel-1))^(2^$A53) | F53: =((F49-1)/(MaxLevel-1))^(2^$A53) | G53: =((G49-1)/(MaxLevel-1))^(2^$A53) | H53: =((H49-1)/(MaxLevel-1))^(2^$A53) | I53: =((I49-1)/(MaxLevel-1))^(2^$A53) | ... K53: =((K49-1)/(MaxLevel-1))^(2^$A53)
A54: 0.5 | B54: =((B49-1)/(MaxLevel-1))^(2^$A54) | C54: =((C49-1)/(MaxLevel-1))^(2^$A54) | D54: =((D49-1)/(MaxLevel-1))^(2^$A54) | E54: =((E49-1)/(MaxLevel-1))^(2^$A54) | F54: =((F49-1)/(MaxLevel-1))^(2^$A54) | G54: =((G49-1)/(MaxLevel-1))^(2^$A54) | H54: =((H49-1)/(MaxLevel-1))^(2^$A54) | I54: =((I49-1)/(MaxLevel-1))^(2^$A54) | ... K54: =((K49-1)/(MaxLevel-1))^(2^$A54)
A55: 1 | B55: =((B49-1)/(MaxLevel-1))^(2^$A55) | C55: =((C49-1)/(MaxLevel-1))^(2^$A55) | D55: =((D49-1)/(MaxLevel-1))^(2^$A55) | E55: =((E49-1)/(MaxLevel-1))^(2^$A55) | F55: =((F49-1)/(MaxLevel-1))^(2^$A55) | G55: =((G49-1)/(MaxLevel-1))^(2^$A55) | H55: =((H49-1)/(MaxLevel-1))^(2^$A55) | I55: =((I49-1)/(MaxLevel-1))^(2^$A55) | ... K55: =((K49-1)/(MaxLevel-1))^(2^$A55)
A56: 2 | B56: =((B49-1)/(MaxLevel-1))^(2^$A56) | C56: =((C49-1)/(MaxLevel-1))^(2^$A56) | D56: =((D49-1)/(MaxLevel-1))^(2^$A56) | E56: =((E49-1)/(MaxLevel-1))^(2^$A56) | F56: =((F49-1)/(MaxLevel-1))^(2^$A56) | G56: =((G49-1)/(MaxLevel-1))^(2^$A56) | H56: =((H49-1)/(MaxLevel-1))^(2^$A56) | I56: =((I49-1)/(MaxLevel-1))^(2^$A56) | ... K56: =((K49-1)/(MaxLevel-1))^(2^$A56)

Sheet DamageTypes
A1: DamageTypeID | B1: DisplayName | C1: Category | D1: Description
A2: Slash | B2: Slashing | C2: Physical | D2: Blades, claws
A3: Pierce | B3: Piercing | C3: Physical | D3: Arrows, spears, bites
A4: Blunt | B4: Blunt | C4: Physical | D4: Clubs, fists, crushing
A5: Fire | B5: Fire | C5: Magical | D5: Placeholder – replace with your own list
A6: Cold | B6: Cold | C6: Magical
A7: Lightning | B7: Lightning | C7: Magical
A8: Poison | B8: Poison | C8: Magical
A9: Holy | B9: Holy | C9: Magical
A10: Unholy | B10: Unholy | C10: Magical

Sheet Abilities
A1: AbilityID | B1: DisplayName | C1: Description | D1: Kind | E1: Targeting | F1: Delivery | G1: DamageType | H1: BasePower | I1: ScalingStat | J1: ScalingFactor | K1: Range | L1: AreaRadius | M1: Cooldown | N1: CastTime | O1: StatusEffect | P1: StatusChance | Q1: StatusDuration | R1: StatusMagnitude
A2: A_Strike | B2: Strike | C2: A basic melee blow. | D2: Attack | E2: SingleEnemy | F2: Melee | G2: Slash | H2: 5 | I2: Strength | J2: 1 | K2: 1 | L2: 0 | M2: 1.5 | N2: 0
A3: A_Arrow | B3: Arrow Volley | C3: Looses a flight of arrows at one foe. | D3: Attack | E3: SingleEnemy | F3: Ranged | G3: Pierce | H3: 3 | I3: Strength | J3: 0.8 | K3: 6 | L3: 0 | M3: 2 | N3: 0.3
A4: A_Fireball | B4: Fireball | C4: Hurls fire that bursts on impact, setting targets alight. | D4: Attack | E4: AreaEnemy | F4: Magic | G4: Fire | H4: 8 | I4: Magic | J4: 1.2 | K4: 5 | L4: 1.5 | M4: 6 | N4: 0.8 | O4: Burn | P4: 0.5 | Q4: 3 | R4: 2
A5: A_Stoneskin | B5: Stoneskin | C5: Hardens the minion's hide, absorbing damage. | D5: Defence | E5: Self | F5: Magic | H5: 10 | I5: Fortitude | J5: 0.5 | K5: 0 | L5: 0 | M5: 20 | N5: 0.5 | O5: Shield | P5: 1 | Q5: 8 | R5: 15
A6: A_Howl | B6: Terrible Howl | C6: Nearby enemies may flee in fear. | D6: Debuff | E6: AreaEnemy | F6: Magic | G6: Unholy | H6: 0 | I6: Magic | J6: 0 | K6: 0 | L6: 3 | M6: 15 | N6: 0.5 | O6: Fear | P6: 0.4 | Q6: 3

Sheet 01U_Data
A1: FactionID | B1: MinionID | C1: Display Name | D1: Stance | E1: Movement | F1: Dmg_Slash | G1: Dmg_Pierce | H1: Dmg_Blunt | I1: Dmg_Fire | J1: Dmg_Cold | K1: Dmg_Lightning | L1: Dmg_Poison | M1: Dmg_Holy | N1: Dmg_Unholy | O1: ResearchPreference | P1: TrainPreference | Q1: BuildPreference | R1: PrayPreference | S1: TorturePreference | T1: Gain1 | U1: Ability1 | V1: Gain2 | W1: Ability2 | X1: Gain3 | Y1: Ability3 | Z1: Gain4 | AA1: Ability4 | AB1: Gain5 | AC1: Ability5 | AD1: Summonable | AE1: WorkerJobs | AF1: SummonWeight | AG1: PopulationCost | AH1: RequiredRooms | AI1: MinRoomTiles | AJ1: RequiredResearch
A2: 01U | B2: C1 | C2: Thanatos | D2: Commander | E2: LandOnly | M2: 2 | N2: 0.5 | O2: 0.2 | P2: 0.6 | Q2: 0.1 | R2: 0.1 | S2: 0 | T2: 1 | U2: A_Strike | V2: 4 | W2: A_Howl | AD2: FALSE
A3: 01U | B3: T1M | C3: Stymphalian Bird | D3: Mage | E3: Flying | G3: 2 | I3: 0.5 | K3: 2 | O3: 0.6 | P3: 0.2 | Q3: 0 | R3: 0.1 | S3: 0.1 | T3: 1 | U3: A_Arrow | V3: 5 | W3: A_Fireball | AD3: TRUE | AF3: 1 | AG3: 1 | AH3: RoomA | AI3: 9
A4: 01U | B4: T2F | C4: Minotaur | D4: Fighter | E4: LandOnly | F4: 0.5 | G4: 0.5 | H4: 1.5 | O4: 0 | P4: 0.7 | Q4: 0.2 | R4: 0 | S4: 0.1 | T4: 1 | U4: A_Strike | V4: 3 | W4: A_Stoneskin | AD4: TRUE | AE4: TRUE | AF4: 0.6 | AG4: 2 | AH4: RoomA;RoomB | AI4: 9;4 | AJ4: Labyrinths
A5: 01U | B5: W | C5: Eidolon | D5: Worker | E5: LandOnly | O5: 0 | P5: 0 | Q5: 1 | R5: 0 | S5: 0

Sheet 01U_Levels
A1: FactionID | B1: MinionID | C1: Stat | D1: Min | E1: Max | F1: Curve | G1: Skew | H1: L1 | I1: L2 | J1: L3 | K1: L4 | L1: L5 | M1: L6 | N1: L7 | O1: L8 | P1: L9 | Q1: L10
A2: 01U | B2: C1 | C2: Experience | D2: 0 | E2: 20000 | F2: 1 | G2: 0 | H2: =IF(OR(D2="",E2=""),"",IF(IFERROR(INDEX(Stats!$D:$D,MATCH($C2,Stats!$A:$A,0)),FALSE),ROUND(D2+(E2-D2)*(1+G2)*((1-1)/(MaxLevel-1))^(2^F2),0),D2+(E2-D2)*(1+G2)*((1-1)/(MaxLevel-1))^(2^F2))) | I2: =IF(OR(D2="",E2=""),"",IF(IFERROR(INDEX(Stats!$D:$D,MATCH($C2,Stats!$A:$A,0)),FALSE),ROUND(D2+(E2-D2)*(1+G2)*((2-1)/(MaxLevel-1))^(2^F2),0),D2+(E2-D2)*(1+G2)*((2-1)/(MaxLevel-1))^(2^F2))) | J2: =IF(OR(D2="",E2=""),"",IF(IFERROR(INDEX(Stats!$D:$D,MATCH($C2,Stats!$A:$A,0)),FALSE),ROUND(D2+(E2-D2)*(1+G2)*((3-1)/(MaxLevel-1))^(2^F2),0),D2+(E2-D2)*(1+G2)*((3-1)/(MaxLevel-1))^(2^F2))) | K2: =IF(OR(D2="",E2=""),"",IF(IFERROR(INDEX(Stats!$D:$D,MATCH($C2,Stats!$A:$A,0)),FALSE),ROUND(D2+(E2-D2)*(1+G2)*((4-1)/(MaxLevel-1))^(2^F2),0),D2+(E2-D2)*(1+G2)*((4-1)/(MaxLevel-1))^(2^F2))) | L2: =IF(OR(D2="",E2=""),"",IF(IFERROR(INDEX(Stats!$D:$D,MATCH($C2,Stats!$A:$A,0)),FALSE),ROUND(D2+(E2-D2)*(1+G2)*((5-1)/(MaxLevel-1))^(2^F2),0),D2+(E2-D2)*(1+G2)*((5-1)/(MaxLevel-1))^(2^F2))) | M2: =IF(OR(D2="",E2=""),"",IF(IFERROR(INDEX(Stats!$D:$D,MATCH($C2,Stats!$A:$A,0)),FALSE),ROUND(D2+(E2-D2)*(1+G2)*((6-1)/(MaxLevel-1))^(2^F2),0),D2+(E2-D2)*(1+G2)*((6-1)/(MaxLevel-1))^(2^F2))) | N2: =IF(OR(D2="",E2=""),"",IF(IFERROR(INDEX(Stats!$D:$D,MATCH($C2,Stats!$A:$A,0)),FALSE),ROUND(D2+(E2-D2)*(1+G2)*((7-1)/(MaxLevel-1))^(2^F2),0),D2+(E2-D2)*(1+G2)*((7-1)/(MaxLevel-1))^(2^F2))) | O2: =IF(OR(D2="",E2=""),"",IF(IFERROR(INDEX(Stats!$D:$D,MATCH($C2,Stats!$A:$A,0)),FALSE),ROUND(D2+(E2-D2)*(1+G2)*((8-1)/(MaxLevel-1))^(2^F2),0),D2+(E2-D2)*(1+G2)*((8-1)/(MaxLevel-1))^(2^F2))) | P2: =IF(OR(D2="",E2=""),"",IF(IFERROR(INDEX(Stats!$D:$D,MATCH($C2,Stats!$A:$A,0)),FALSE),ROUND(D2+(E2-D2)*(1+G2)*((9-1)/(MaxLevel-1))^(2^F2),0),D2+(E2-D2)*(1+G2)*((9-1)/(MaxLevel-1))^(2^F2))) | Q2: =IF(OR(D2="",E2=""),"",IF(IFERROR(INDEX(Stats!$D:$D,MATCH($C2,Stats!$A:$A,0)),FALSE),ROUND(D2+(E2-D2)*(1+G2)*((10-1)/(MaxLevel-1))^(2^F2),0),D2+(E2-D2)*(1+G2)*((10-1)/(MaxLevel-1))^(2^F2)))
A3: 01U | B3: C1 | C3: Salary | D3: 50 | E3: 300 | F3: 0 | G3: 0 | H3: =IF(OR(D3="",E3=""),"",IF(IFERROR(INDEX(Stats!$D:$D,MATCH($C3,Stats!$A:$A,0)),FALSE),ROUND(D3+(E3-D3)*(1+G3)*((1-1)/(MaxLevel-1))^(2^F3),0),D3+(E3-D3)*(1+G3)*((1-1)/(MaxLevel-1))^(2^F3))) | I3: =IF(OR(D3="",E3=""),"",IF(IFERROR(INDEX(Stats!$D:$D,MATCH($C3,Stats!$A:$A,0)),FALSE),ROUND(D3+(E3-D3)*(1+G3)*((2-1)/(MaxLevel-1))^(2^F3),0),D3+(E3-D3)*(1+G3)*((2-1)/(MaxLevel-1))^(2^F3))) | J3: =IF(OR(D3="",E3=""),"",IF(IFERROR(INDEX(Stats!$D:$D,MATCH($C3,Stats!$A:$A,0)),FALSE),ROUND(D3+(E3-D3)*(1+G3)*((3-1)/(MaxLevel-1))^(2^F3),0),D3+(E3-D3)*(1+G3)*((3-1)/(MaxLevel-1))^(2^F3))) | K3: =IF(OR(D3="",E3=""),"",IF(IFERROR(INDEX(Stats!$D:$D,MATCH($C3,Stats!$A:$A,0)),FALSE),ROUND(D3+(E3-D3)*(1+G3)*((4-1)/(MaxLevel-1))^(2^F3),0),D3+(E3-D3)*(1+G3)*((4-1)/(MaxLevel-1))^(2^F3))) | L3: =IF(OR(D3="",E3=""),"",IF(IFERROR(INDEX(Stats!$D:$D,MATCH($C3,Stats!$A:$A,0)),FALSE),ROUND(D3+(E3-D3)*(1+G3)*((5-1)/(MaxLevel-1))^(2^F3),0),D3+(E3-D3)*(1+G3)*((5-1)/(MaxLevel-1))^(2^F3))) | M3: =IF(OR(D3="",E3=""),"",IF(IFERROR(INDEX(Stats!$D:$D,MATCH($C3,Stats!$A:$A,0)),FALSE),ROUND(D3+(E3-D3)*(1+G3)*((6-1)/(MaxLevel-1))^(2^F3),0),D3+(E3-D3)*(1+G3)*((6-1)/(MaxLevel-1))^(2^F3))) | N3: =IF(OR(D3="",E3=""),"",IF(IFERROR(INDEX(Stats!$D:$D,MATCH($C3,Stats!$A:$A,0)),FALSE),ROUND(D3+(E3-D3)*(1+G3)*((7-1)/(MaxLevel-1))^(2^F3),0),D3+(E3-D3)*(1+G3)*((7-1)/(MaxLevel-1))^(2^F3))) | O3: =IF(OR(D3="",E3=""),"",IF(IFERROR(INDEX(Stats!$D:$D,MATCH($C3,Stats!$A:$A,0)),FALSE),ROUND(D3+(E3-D3)*(1+G3)*((8-1)/(MaxLevel-1))^(2^F3),0),D3+(E3-D3)*(1+G3)*((8-1)/(MaxLevel-1))^(2^F3))) | P3: =IF(OR(D3="",E3=""),"",IF(IFERROR(INDEX(Stats!$D:$D,MATCH($C3,Stats!$A:$A,0)),FALSE),ROUND(D3+(E3-D3)*(1+G3)*((9-1)/(MaxLevel-1))^(2^F3),0),D3+(E3-D3)*(1+G3)*((9-1)/(MaxLevel-1))^(2^F3))) | Q3: =IF(OR(D3="",E3=""),"",IF(IFERROR(INDEX(Stats!$D:$D,MATCH($C3,Stats!$A:$A,0)),FALSE),ROUND(D3+(E3-D3)*(1+G3)*((10-1)/(MaxLevel-1))^(2^F3),0),D3+(E3-D3)*(1+G3)*((10-1)/(MaxLevel-1))^(2^F3)))
A4: 01U | B4: C1 | C4: Health | D4: 400 | E4: 1600 | F4: 0 | G4: 0 | H4: =IF(OR(D4="",E4=""),"",IF(IFERROR(INDEX(Stats!$D:$D,MATCH($C4,Stats!$A:$A,0)),FALSE),ROUND(D4+(E4-D4)*(1+G4)*((1-1)/(MaxLevel-1))^(2^F4),0),D4+(E4-D4)*(1+G4)*((1-1)/(MaxLevel-1))^(2^F4))) | I4: =IF(OR(D4="",E4=""),"",IF(IFERROR(INDEX(Stats!$D:$D,MATCH($C4,Stats!$A:$A,0)),FALSE),ROUND(D4+(E4-D4)*(1+G4)*((2-1)/(MaxLevel-1))^(2^F4),0),D4+(E4-D4)*(1+G4)*((2-1)/(MaxLevel-1))^(2^F4))) | J4: =IF(OR(D4="",E4=""),"",IF(IFERROR(INDEX(Stats!$D:$D,MATCH($C4,Stats!$A:$A,0)),FALSE),ROUND(D4+(E4-D4)*(1+G4)*((3-1)/(MaxLevel-1))^(2^F4),0),D4+(E4-D4)*(1+G4)*((3-1)/(MaxLevel-1))^(2^F4))) | K4: =IF(OR(D4="",E4=""),"",IF(IFERROR(INDEX(Stats!$D:$D,MATCH($C4,Stats!$A:$A,0)),FALSE),ROUND(D4+(E4-D4)*(1+G4)*((4-1)/(MaxLevel-1))^(2^F4),0),D4+(E4-D4)*(1+G4)*((4-1)/(MaxLevel-1))^(2^F4))) | L4: =IF(OR(D4="",E4=""),"",IF(IFERROR(INDEX(Stats!$D:$D,MATCH($C4,Stats!$A:$A,0)),FALSE),ROUND(D4+(E4-D4)*(1+G4)*((5-1)/(MaxLevel-1))^(2^F4),0),D4+(E4-D4)*(1+G4)*((5-1)/(MaxLevel-1))^(2^F4))) | M4: =IF(OR(D4="",E4=""),"",IF(IFERROR(INDEX(Stats!$D:$D,MATCH($C4,Stats!$A:$A,0)),FALSE),ROUND(D4+(E4-D4)*(1+G4)*((6-1)/(MaxLevel-1))^(2^F4),0),D4+(E4-D4)*(1+G4)*((6-1)/(MaxLevel-1))^(2^F4))) | N4: =IF(OR(D4="",E4=""),"",IF(IFERROR(INDEX(Stats!$D:$D,MATCH($C4,Stats!$A:$A,0)),FALSE),ROUND(D4+(E4-D4)*(1+G4)*((7-1)/(MaxLevel-1))^(2^F4),0),D4+(E4-D4)*(1+G4)*((7-1)/(MaxLevel-1))^(2^F4))) | O4: =IF(OR(D4="",E4=""),"",IF(IFERROR(INDEX(Stats!$D:$D,MATCH($C4,Stats!$A:$A,0)),FALSE),ROUND(D4+(E4-D4)*(1+G4)*((8-1)/(MaxLevel-1))^(2^F4),0),D4+(E4-D4)*(1+G4)*((8-1)/(MaxLevel-1))^(2^F4))) | P4: =IF(OR(D4="",E4=""),"",IF(IFERROR(INDEX(Stats!$D:$D,MATCH($C4,Stats!$A:$A,0)),FALSE),ROUND(D4+(E4-D4)*(1+G4)*((9-1)/(MaxLevel-1))^(2^F4),0),D4+(E4-D4)*(1+G4)*((9-1)/(MaxLevel-1))^(2^F4))) | Q4: =IF(OR(D4="",E4=""),"",IF(IFERROR(INDEX(Stats!$D:$D,MATCH($C4,Stats!$A:$A,0)),FALSE),ROUND(D4+(E4-D4)*(1+G4)*((10-1)/(MaxLevel-1))^(2^F4),0),D4+(E4-D4)*(1+G4)*((10-1)/(MaxLevel-1))^(2^F4)))
A5: 01U | B5: C1 | C5: Strength | D5: 30 | E5: 120 | F5: 0 | G5: 0 | H5: =IF(OR(D5="",E5=""),"",IF(IFERROR(INDEX(Stats!$D:$D,MATCH($C5,Stats!$A:$A,0)),FALSE),ROUND(D5+(E5-D5)*(1+G5)*((1-1)/(MaxLevel-1))^(2^F5),0),D5+(E5-D5)*(1+G5)*((1-1)/(MaxLevel-1))^(2^F5))) | I5: =IF(OR(D5="",E5=""),"",IF(IFERROR(INDEX(Stats!$D:$D,MATCH($C5,Stats!$A:$A,0)),FALSE),ROUND(D5+(E5-D5)*(1+G5)*((2-1)/(MaxLevel-1))^(2^F5),0),D5+(E5-D5)*(1+G5)*((2-1)/(MaxLevel-1))^(2^F5))) | J5: =IF(OR(D5="",E5=""),"",IF(IFERROR(INDEX(Stats!$D:$D,MATCH($C5,Stats!$A:$A,0)),FALSE),ROUND(D5+(E5-D5)*(1+G5)*((3-1)/(MaxLevel-1))^(2^F5),0),D5+(E5-D5)*(1+G5)*((3-1)/(MaxLevel-1))^(2^F5))) | K5: =IF(OR(D5="",E5=""),"",IF(IFERROR(INDEX(Stats!$D:$D,MATCH($C5,Stats!$A:$A,0)),FALSE),ROUND(D5+(E5-D5)*(1+G5)*((4-1)/(MaxLevel-1))^(2^F5),0),D5+(E5-D5)*(1+G5)*((4-1)/(MaxLevel-1))^(2^F5))) | L5: =IF(OR(D5="",E5=""),"",IF(IFERROR(INDEX(Stats!$D:$D,MATCH($C5,Stats!$A:$A,0)),FALSE),ROUND(D5+(E5-D5)*(1+G5)*((5-1)/(MaxLevel-1))^(2^F5),0),D5+(E5-D5)*(1+G5)*((5-1)/(MaxLevel-1))^(2^F5))) | M5: =IF(OR(D5="",E5=""),"",IF(IFERROR(INDEX(Stats!$D:$D,MATCH($C5,Stats!$A:$A,0)),FALSE),ROUND(D5+(E5-D5)*(1+G5)*((6-1)/(MaxLevel-1))^(2^F5),0),D5+(E5-D5)*(1+G5)*((6-1)/(MaxLevel-1))^(2^F5))) | N5: =IF(OR(D5="",E5=""),"",IF(IFERROR(INDEX(Stats!$D:$D,MATCH($C5,Stats!$A:$A,0)),FALSE),ROUND(D5+(E5-D5)*(1+G5)*((7-1)/(MaxLevel-1))^(2^F5),0),D5+(E5-D5)*(1+G5)*((7-1)/(MaxLevel-1))^(2^F5))) | O5: =IF(OR(D5="",E5=""),"",IF(IFERROR(INDEX(Stats!$D:$D,MATCH($C5,Stats!$A:$A,0)),FALSE),ROUND(D5+(E5-D5)*(1+G5)*((8-1)/(MaxLevel-1))^(2^F5),0),D5+(E5-D5)*(1+G5)*((8-1)/(MaxLevel-1))^(2^F5))) | P5: =IF(OR(D5="",E5=""),"",IF(IFERROR(INDEX(Stats!$D:$D,MATCH($C5,Stats!$A:$A,0)),FALSE),ROUND(D5+(E5-D5)*(1+G5)*((9-1)/(MaxLevel-1))^(2^F5),0),D5+(E5-D5)*(1+G5)*((9-1)/(MaxLevel-1))^(2^F5))) | Q5: =IF(OR(D5="",E5=""),"",IF(IFERROR(INDEX(Stats!$D:$D,MATCH($C5,Stats!$A:$A,0)),FALSE),ROUND(D5+(E5-D5)*(1+G5)*((10-1)/(MaxLevel-1))^(2^F5),0),D5+(E5-D5)*(1+G5)*((10-1)/(MaxLevel-1))^(2^F5)))
A6: 01U | B6: C1 | C6: Accuracy | D6: 0.7 | E6: 0.95 | F6: -1 | G6: 0 | H6: =IF(OR(D6="",E6=""),"",IF(IFERROR(INDEX(Stats!$D:$D,MATCH($C6,Stats!$A:$A,0)),FALSE),ROUND(D6+(E6-D6)*(1+G6)*((1-1)/(MaxLevel-1))^(2^F6),0),D6+(E6-D6)*(1+G6)*((1-1)/(MaxLevel-1))^(2^F6))) | I6: =IF(OR(D6="",E6=""),"",IF(IFERROR(INDEX(Stats!$D:$D,MATCH($C6,Stats!$A:$A,0)),FALSE),ROUND(D6+(E6-D6)*(1+G6)*((2-1)/(MaxLevel-1))^(2^F6),0),D6+(E6-D6)*(1+G6)*((2-1)/(MaxLevel-1))^(2^F6))) | J6: =IF(OR(D6="",E6=""),"",IF(IFERROR(INDEX(Stats!$D:$D,MATCH($C6,Stats!$A:$A,0)),FALSE),ROUND(D6+(E6-D6)*(1+G6)*((3-1)/(MaxLevel-1))^(2^F6),0),D6+(E6-D6)*(1+G6)*((3-1)/(MaxLevel-1))^(2^F6))) | K6: =IF(OR(D6="",E6=""),"",IF(IFERROR(INDEX(Stats!$D:$D,MATCH($C6,Stats!$A:$A,0)),FALSE),ROUND(D6+(E6-D6)*(1+G6)*((4-1)/(MaxLevel-1))^(2^F6),0),D6+(E6-D6)*(1+G6)*((4-1)/(MaxLevel-1))^(2^F6))) | L6: =IF(OR(D6="",E6=""),"",IF(IFERROR(INDEX(Stats!$D:$D,MATCH($C6,Stats!$A:$A,0)),FALSE),ROUND(D6+(E6-D6)*(1+G6)*((5-1)/(MaxLevel-1))^(2^F6),0),D6+(E6-D6)*(1+G6)*((5-1)/(MaxLevel-1))^(2^F6))) | M6: =IF(OR(D6="",E6=""),"",IF(IFERROR(INDEX(Stats!$D:$D,MATCH($C6,Stats!$A:$A,0)),FALSE),ROUND(D6+(E6-D6)*(1+G6)*((6-1)/(MaxLevel-1))^(2^F6),0),D6+(E6-D6)*(1+G6)*((6-1)/(MaxLevel-1))^(2^F6))) | N6: =IF(OR(D6="",E6=""),"",IF(IFERROR(INDEX(Stats!$D:$D,MATCH($C6,Stats!$A:$A,0)),FALSE),ROUND(D6+(E6-D6)*(1+G6)*((7-1)/(MaxLevel-1))^(2^F6),0),D6+(E6-D6)*(1+G6)*((7-1)/(MaxLevel-1))^(2^F6))) | O6: =IF(OR(D6="",E6=""),"",IF(IFERROR(INDEX(Stats!$D:$D,MATCH($C6,Stats!$A:$A,0)),FALSE),ROUND(D6+(E6-D6)*(1+G6)*((8-1)/(MaxLevel-1))^(2^F6),0),D6+(E6-D6)*(1+G6)*((8-1)/(MaxLevel-1))^(2^F6))) | P6: =IF(OR(D6="",E6=""),"",IF(IFERROR(INDEX(Stats!$D:$D,MATCH($C6,Stats!$A:$A,0)),FALSE),ROUND(D6+(E6-D6)*(1+G6)*((9-1)/(MaxLevel-1))^(2^F6),0),D6+(E6-D6)*(1+G6)*((9-1)/(MaxLevel-1))^(2^F6))) | Q6: =IF(OR(D6="",E6=""),"",IF(IFERROR(INDEX(Stats!$D:$D,MATCH($C6,Stats!$A:$A,0)),FALSE),ROUND(D6+(E6-D6)*(1+G6)*((10-1)/(MaxLevel-1))^(2^F6),0),D6+(E6-D6)*(1+G6)*((10-1)/(MaxLevel-1))^(2^F6)))
A7: 01U | B7: C1 | C7: Dexterity | D7: 0.1 | E7: 0.3 | F7: 0 | G7: 0 | H7: =IF(OR(D7="",E7=""),"",IF(IFERROR(INDEX(Stats!$D:$D,MATCH($C7,Stats!$A:$A,0)),FALSE),ROUND(D7+(E7-D7)*(1+G7)*((1-1)/(MaxLevel-1))^(2^F7),0),D7+(E7-D7)*(1+G7)*((1-1)/(MaxLevel-1))^(2^F7))) | I7: =IF(OR(D7="",E7=""),"",IF(IFERROR(INDEX(Stats!$D:$D,MATCH($C7,Stats!$A:$A,0)),FALSE),ROUND(D7+(E7-D7)*(1+G7)*((2-1)/(MaxLevel-1))^(2^F7),0),D7+(E7-D7)*(1+G7)*((2-1)/(MaxLevel-1))^(2^F7))) | J7: =IF(OR(D7="",E7=""),"",IF(IFERROR(INDEX(Stats!$D:$D,MATCH($C7,Stats!$A:$A,0)),FALSE),ROUND(D7+(E7-D7)*(1+G7)*((3-1)/(MaxLevel-1))^(2^F7),0),D7+(E7-D7)*(1+G7)*((3-1)/(MaxLevel-1))^(2^F7))) | K7: =IF(OR(D7="",E7=""),"",IF(IFERROR(INDEX(Stats!$D:$D,MATCH($C7,Stats!$A:$A,0)),FALSE),ROUND(D7+(E7-D7)*(1+G7)*((4-1)/(MaxLevel-1))^(2^F7),0),D7+(E7-D7)*(1+G7)*((4-1)/(MaxLevel-1))^(2^F7))) | L7: =IF(OR(D7="",E7=""),"",IF(IFERROR(INDEX(Stats!$D:$D,MATCH($C7,Stats!$A:$A,0)),FALSE),ROUND(D7+(E7-D7)*(1+G7)*((5-1)/(MaxLevel-1))^(2^F7),0),D7+(E7-D7)*(1+G7)*((5-1)/(MaxLevel-1))^(2^F7))) | M7: =IF(OR(D7="",E7=""),"",IF(IFERROR(INDEX(Stats!$D:$D,MATCH($C7,Stats!$A:$A,0)),FALSE),ROUND(D7+(E7-D7)*(1+G7)*((6-1)/(MaxLevel-1))^(2^F7),0),D7+(E7-D7)*(1+G7)*((6-1)/(MaxLevel-1))^(2^F7))) | N7: =IF(OR(D7="",E7=""),"",IF(IFERROR(INDEX(Stats!$D:$D,MATCH($C7,Stats!$A:$A,0)),FALSE),ROUND(D7+(E7-D7)*(1+G7)*((7-1)/(MaxLevel-1))^(2^F7),0),D7+(E7-D7)*(1+G7)*((7-1)/(MaxLevel-1))^(2^F7))) | O7: =IF(OR(D7="",E7=""),"",IF(IFERROR(INDEX(Stats!$D:$D,MATCH($C7,Stats!$A:$A,0)),FALSE),ROUND(D7+(E7-D7)*(1+G7)*((8-1)/(MaxLevel-1))^(2^F7),0),D7+(E7-D7)*(1+G7)*((8-1)/(MaxLevel-1))^(2^F7))) | P7: =IF(OR(D7="",E7=""),"",IF(IFERROR(INDEX(Stats!$D:$D,MATCH($C7,Stats!$A:$A,0)),FALSE),ROUND(D7+(E7-D7)*(1+G7)*((9-1)/(MaxLevel-1))^(2^F7),0),D7+(E7-D7)*(1+G7)*((9-1)/(MaxLevel-1))^(2^F7))) | Q7: =IF(OR(D7="",E7=""),"",IF(IFERROR(INDEX(Stats!$D:$D,MATCH($C7,Stats!$A:$A,0)),FALSE),ROUND(D7+(E7-D7)*(1+G7)*((10-1)/(MaxLevel-1))^(2^F7),0),D7+(E7-D7)*(1+G7)*((10-1)/(MaxLevel-1))^(2^F7)))
A8: 01U | B8: C1 | C8: Fortitude | H8: =IF(OR(D8="",E8=""),"",IF(IFERROR(INDEX(Stats!$D:$D,MATCH($C8,Stats!$A:$A,0)),FALSE),ROUND(D8+(E8-D8)*(1+G8)*((1-1)/(MaxLevel-1))^(2^F8),0),D8+(E8-D8)*(1+G8)*((1-1)/(MaxLevel-1))^(2^F8))) | I8: =IF(OR(D8="",E8=""),"",IF(IFERROR(INDEX(Stats!$D:$D,MATCH($C8,Stats!$A:$A,0)),FALSE),ROUND(D8+(E8-D8)*(1+G8)*((2-1)/(MaxLevel-1))^(2^F8),0),D8+(E8-D8)*(1+G8)*((2-1)/(MaxLevel-1))^(2^F8))) | J8: =IF(OR(D8="",E8=""),"",IF(IFERROR(INDEX(Stats!$D:$D,MATCH($C8,Stats!$A:$A,0)),FALSE),ROUND(D8+(E8-D8)*(1+G8)*((3-1)/(MaxLevel-1))^(2^F8),0),D8+(E8-D8)*(1+G8)*((3-1)/(MaxLevel-1))^(2^F8))) | K8: =IF(OR(D8="",E8=""),"",IF(IFERROR(INDEX(Stats!$D:$D,MATCH($C8,Stats!$A:$A,0)),FALSE),ROUND(D8+(E8-D8)*(1+G8)*((4-1)/(MaxLevel-1))^(2^F8),0),D8+(E8-D8)*(1+G8)*((4-1)/(MaxLevel-1))^(2^F8))) | L8: =IF(OR(D8="",E8=""),"",IF(IFERROR(INDEX(Stats!$D:$D,MATCH($C8,Stats!$A:$A,0)),FALSE),ROUND(D8+(E8-D8)*(1+G8)*((5-1)/(MaxLevel-1))^(2^F8),0),D8+(E8-D8)*(1+G8)*((5-1)/(MaxLevel-1))^(2^F8))) | M8: =IF(OR(D8="",E8=""),"",IF(IFERROR(INDEX(Stats!$D:$D,MATCH($C8,Stats!$A:$A,0)),FALSE),ROUND(D8+(E8-D8)*(1+G8)*((6-1)/(MaxLevel-1))^(2^F8),0),D8+(E8-D8)*(1+G8)*((6-1)/(MaxLevel-1))^(2^F8))) | N8: =IF(OR(D8="",E8=""),"",IF(IFERROR(INDEX(Stats!$D:$D,MATCH($C8,Stats!$A:$A,0)),FALSE),ROUND(D8+(E8-D8)*(1+G8)*((7-1)/(MaxLevel-1))^(2^F8),0),D8+(E8-D8)*(1+G8)*((7-1)/(MaxLevel-1))^(2^F8))) | O8: =IF(OR(D8="",E8=""),"",IF(IFERROR(INDEX(Stats!$D:$D,MATCH($C8,Stats!$A:$A,0)),FALSE),ROUND(D8+(E8-D8)*(1+G8)*((8-1)/(MaxLevel-1))^(2^F8),0),D8+(E8-D8)*(1+G8)*((8-1)/(MaxLevel-1))^(2^F8))) | P8: =IF(OR(D8="",E8=""),"",IF(IFERROR(INDEX(Stats!$D:$D,MATCH($C8,Stats!$A:$A,0)),FALSE),ROUND(D8+(E8-D8)*(1+G8)*((9-1)/(MaxLevel-1))^(2^F8),0),D8+(E8-D8)*(1+G8)*((9-1)/(MaxLevel-1))^(2^F8))) | Q8: =IF(OR(D8="",E8=""),"",IF(IFERROR(INDEX(Stats!$D:$D,MATCH($C8,Stats!$A:$A,0)),FALSE),ROUND(D8+(E8-D8)*(1+G8)*((10-1)/(MaxLevel-1))^(2^F8),0),D8+(E8-D8)*(1+G8)*((10-1)/(MaxLevel-1))^(2^F8)))
A9: 01U | B9: C1 | C9: Speed | H9: =IF(OR(D9="",E9=""),"",IF(IFERROR(INDEX(Stats!$D:$D,MATCH($C9,Stats!$A:$A,0)),FALSE),ROUND(D9+(E9-D9)*(1+G9)*((1-1)/(MaxLevel-1))^(2^F9),0),D9+(E9-D9)*(1+G9)*((1-1)/(MaxLevel-1))^(2^F9))) | I9: =IF(OR(D9="",E9=""),"",IF(IFERROR(INDEX(Stats!$D:$D,MATCH($C9,Stats!$A:$A,0)),FALSE),ROUND(D9+(E9-D9)*(1+G9)*((2-1)/(MaxLevel-1))^(2^F9),0),D9+(E9-D9)*(1+G9)*((2-1)/(MaxLevel-1))^(2^F9))) | J9: =IF(OR(D9="",E9=""),"",IF(IFERROR(INDEX(Stats!$D:$D,MATCH($C9,Stats!$A:$A,0)),FALSE),ROUND(D9+(E9-D9)*(1+G9)*((3-1)/(MaxLevel-1))^(2^F9),0),D9+(E9-D9)*(1+G9)*((3-1)/(MaxLevel-1))^(2^F9))) | K9: =IF(OR(D9="",E9=""),"",IF(IFERROR(INDEX(Stats!$D:$D,MATCH($C9,Stats!$A:$A,0)),FALSE),ROUND(D9+(E9-D9)*(1+G9)*((4-1)/(MaxLevel-1))^(2^F9),0),D9+(E9-D9)*(1+G9)*((4-1)/(MaxLevel-1))^(2^F9))) | L9: =IF(OR(D9="",E9=""),"",IF(IFERROR(INDEX(Stats!$D:$D,MATCH($C9,Stats!$A:$A,0)),FALSE),ROUND(D9+(E9-D9)*(1+G9)*((5-1)/(MaxLevel-1))^(2^F9),0),D9+(E9-D9)*(1+G9)*((5-1)/(MaxLevel-1))^(2^F9))) | M9: =IF(OR(D9="",E9=""),"",IF(IFERROR(INDEX(Stats!$D:$D,MATCH($C9,Stats!$A:$A,0)),FALSE),ROUND(D9+(E9-D9)*(1+G9)*((6-1)/(MaxLevel-1))^(2^F9),0),D9+(E9-D9)*(1+G9)*((6-1)/(MaxLevel-1))^(2^F9))) | N9: =IF(OR(D9="",E9=""),"",IF(IFERROR(INDEX(Stats!$D:$D,MATCH($C9,Stats!$A:$A,0)),FALSE),ROUND(D9+(E9-D9)*(1+G9)*((7-1)/(MaxLevel-1))^(2^F9),0),D9+(E9-D9)*(1+G9)*((7-1)/(MaxLevel-1))^(2^F9))) | O9: =IF(OR(D9="",E9=""),"",IF(IFERROR(INDEX(Stats!$D:$D,MATCH($C9,Stats!$A:$A,0)),FALSE),ROUND(D9+(E9-D9)*(1+G9)*((8-1)/(MaxLevel-1))^(2^F9),0),D9+(E9-D9)*(1+G9)*((8-1)/(MaxLevel-1))^(2^F9))) | P9: =IF(OR(D9="",E9=""),"",IF(IFERROR(INDEX(Stats!$D:$D,MATCH($C9,Stats!$A:$A,0)),FALSE),ROUND(D9+(E9-D9)*(1+G9)*((9-1)/(MaxLevel-1))^(2^F9),0),D9+(E9-D9)*(1+G9)*((9-1)/(MaxLevel-1))^(2^F9))) | Q9: =IF(OR(D9="",E9=""),"",IF(IFERROR(INDEX(Stats!$D:$D,MATCH($C9,Stats!$A:$A,0)),FALSE),ROUND(D9+(E9-D9)*(1+G9)*((10-1)/(MaxLevel-1))^(2^F9),0),D9+(E9-D9)*(1+G9)*((10-1)/(MaxLevel-1))^(2^F9)))
A10: 01U | B10: C1 | C10: Magic | H10: =IF(OR(D10="",E10=""),"",IF(IFERROR(INDEX(Stats!$D:$D,MATCH($C10,Stats!$A:$A,0)),FALSE),ROUND(D10+(E10-D10)*(1+G10)*((1-1)/(MaxLevel-1))^(2^F10),0),D10+(E10-D10)*(1+G10)*((1-1)/(MaxLevel-1))^(2^F10))) | I10: =IF(OR(D10="",E10=""),"",IF(IFERROR(INDEX(Stats!$D:$D,MATCH($C10,Stats!$A:$A,0)),FALSE),ROUND(D10+(E10-D10)*(1+G10)*((2-1)/(MaxLevel-1))^(2^F10),0),D10+(E10-D10)*(1+G10)*((2-1)/(MaxLevel-1))^(2^F10))) | J10: =IF(OR(D10="",E10=""),"",IF(IFERROR(INDEX(Stats!$D:$D,MATCH($C10,Stats!$A:$A,0)),FALSE),ROUND(D10+(E10-D10)*(1+G10)*((3-1)/(MaxLevel-1))^(2^F10),0),D10+(E10-D10)*(1+G10)*((3-1)/(MaxLevel-1))^(2^F10))) | K10: =IF(OR(D10="",E10=""),"",IF(IFERROR(INDEX(Stats!$D:$D,MATCH($C10,Stats!$A:$A,0)),FALSE),ROUND(D10+(E10-D10)*(1+G10)*((4-1)/(MaxLevel-1))^(2^F10),0),D10+(E10-D10)*(1+G10)*((4-1)/(MaxLevel-1))^(2^F10))) | L10: =IF(OR(D10="",E10=""),"",IF(IFERROR(INDEX(Stats!$D:$D,MATCH($C10,Stats!$A:$A,0)),FALSE),ROUND(D10+(E10-D10)*(1+G10)*((5-1)/(MaxLevel-1))^(2^F10),0),D10+(E10-D10)*(1+G10)*((5-1)/(MaxLevel-1))^(2^F10))) | M10: =IF(OR(D10="",E10=""),"",IF(IFERROR(INDEX(Stats!$D:$D,MATCH($C10,Stats!$A:$A,0)),FALSE),ROUND(D10+(E10-D10)*(1+G10)*((6-1)/(MaxLevel-1))^(2^F10),0),D10+(E10-D10)*(1+G10)*((6-1)/(MaxLevel-1))^(2^F10))) | N10: =IF(OR(D10="",E10=""),"",IF(IFERROR(INDEX(Stats!$D:$D,MATCH($C10,Stats!$A:$A,0)),FALSE),ROUND(D10+(E10-D10)*(1+G10)*((7-1)/(MaxLevel-1))^(2^F10),0),D10+(E10-D10)*(1+G10)*((7-1)/(MaxLevel-1))^(2^F10))) | O10: =IF(OR(D10="",E10=""),"",IF(IFERROR(INDEX(Stats!$D:$D,MATCH($C10,Stats!$A:$A,0)),FALSE),ROUND(D10+(E10-D10)*(1+G10)*((8-1)/(MaxLevel-1))^(2^F10),0),D10+(E10-D10)*(1+G10)*((8-1)/(MaxLevel-1))^(2^F10))) | P10: =IF(OR(D10="",E10=""),"",IF(IFERROR(INDEX(Stats!$D:$D,MATCH($C10,Stats!$A:$A,0)),FALSE),ROUND(D10+(E10-D10)*(1+G10)*((9-1)/(MaxLevel-1))^(2^F10),0),D10+(E10-D10)*(1+G10)*((9-1)/(MaxLevel-1))^(2^F10))) | Q10: =IF(OR(D10="",E10=""),"",IF(IFERROR(INDEX(Stats!$D:$D,MATCH($C10,Stats!$A:$A,0)),FALSE),ROUND(D10+(E10-D10)*(1+G10)*((10-1)/(MaxLevel-1))^(2^F10),0),D10+(E10-D10)*(1+G10)*((10-1)/(MaxLevel-1))^(2^F10)))
A11: 01U | B11: C1 | C11: Resistance | H11: =IF(OR(D11="",E11=""),"",IF(IFERROR(INDEX(Stats!$D:$D,MATCH($C11,Stats!$A:$A,0)),FALSE),ROUND(D11+(E11-D11)*(1+G11)*((1-1)/(MaxLevel-1))^(2^F11),0),D11+(E11-D11)*(1+G11)*((1-1)/(MaxLevel-1))^(2^F11))) | I11: =IF(OR(D11="",E11=""),"",IF(IFERROR(INDEX(Stats!$D:$D,MATCH($C11,Stats!$A:$A,0)),FALSE),ROUND(D11+(E11-D11)*(1+G11)*((2-1)/(MaxLevel-1))^(2^F11),0),D11+(E11-D11)*(1+G11)*((2-1)/(MaxLevel-1))^(2^F11))) | J11: =IF(OR(D11="",E11=""),"",IF(IFERROR(INDEX(Stats!$D:$D,MATCH($C11,Stats!$A:$A,0)),FALSE),ROUND(D11+(E11-D11)*(1+G11)*((3-1)/(MaxLevel-1))^(2^F11),0),D11+(E11-D11)*(1+G11)*((3-1)/(MaxLevel-1))^(2^F11))) | K11: =IF(OR(D11="",E11=""),"",IF(IFERROR(INDEX(Stats!$D:$D,MATCH($C11,Stats!$A:$A,0)),FALSE),ROUND(D11+(E11-D11)*(1+G11)*((4-1)/(MaxLevel-1))^(2^F11),0),D11+(E11-D11)*(1+G11)*((4-1)/(MaxLevel-1))^(2^F11))) | L11: =IF(OR(D11="",E11=""),"",IF(IFERROR(INDEX(Stats!$D:$D,MATCH($C11,Stats!$A:$A,0)),FALSE),ROUND(D11+(E11-D11)*(1+G11)*((5-1)/(MaxLevel-1))^(2^F11),0),D11+(E11-D11)*(1+G11)*((5-1)/(MaxLevel-1))^(2^F11))) | M11: =IF(OR(D11="",E11=""),"",IF(IFERROR(INDEX(Stats!$D:$D,MATCH($C11,Stats!$A:$A,0)),FALSE),ROUND(D11+(E11-D11)*(1+G11)*((6-1)/(MaxLevel-1))^(2^F11),0),D11+(E11-D11)*(1+G11)*((6-1)/(MaxLevel-1))^(2^F11))) | N11: =IF(OR(D11="",E11=""),"",IF(IFERROR(INDEX(Stats!$D:$D,MATCH($C11,Stats!$A:$A,0)),FALSE),ROUND(D11+(E11-D11)*(1+G11)*((7-1)/(MaxLevel-1))^(2^F11),0),D11+(E11-D11)*(1+G11)*((7-1)/(MaxLevel-1))^(2^F11))) | O11: =IF(OR(D11="",E11=""),"",IF(IFERROR(INDEX(Stats!$D:$D,MATCH($C11,Stats!$A:$A,0)),FALSE),ROUND(D11+(E11-D11)*(1+G11)*((8-1)/(MaxLevel-1))^(2^F11),0),D11+(E11-D11)*(1+G11)*((8-1)/(MaxLevel-1))^(2^F11))) | P11: =IF(OR(D11="",E11=""),"",IF(IFERROR(INDEX(Stats!$D:$D,MATCH($C11,Stats!$A:$A,0)),FALSE),ROUND(D11+(E11-D11)*(1+G11)*((9-1)/(MaxLevel-1))^(2^F11),0),D11+(E11-D11)*(1+G11)*((9-1)/(MaxLevel-1))^(2^F11))) | Q11: =IF(OR(D11="",E11=""),"",IF(IFERROR(INDEX(Stats!$D:$D,MATCH($C11,Stats!$A:$A,0)),FALSE),ROUND(D11+(E11-D11)*(1+G11)*((10-1)/(MaxLevel-1))^(2^F11),0),D11+(E11-D11)*(1+G11)*((10-1)/(MaxLevel-1))^(2^F11)))
A12: 01U | B12: C1 | C12: Luck | H12: =IF(OR(D12="",E12=""),"",IF(IFERROR(INDEX(Stats!$D:$D,MATCH($C12,Stats!$A:$A,0)),FALSE),ROUND(D12+(E12-D12)*(1+G12)*((1-1)/(MaxLevel-1))^(2^F12),0),D12+(E12-D12)*(1+G12)*((1-1)/(MaxLevel-1))^(2^F12))) | I12: =IF(OR(D12="",E12=""),"",IF(IFERROR(INDEX(Stats!$D:$D,MATCH($C12,Stats!$A:$A,0)),FALSE),ROUND(D12+(E12-D12)*(1+G12)*((2-1)/(MaxLevel-1))^(2^F12),0),D12+(E12-D12)*(1+G12)*((2-1)/(MaxLevel-1))^(2^F12))) | J12: =IF(OR(D12="",E12=""),"",IF(IFERROR(INDEX(Stats!$D:$D,MATCH($C12,Stats!$A:$A,0)),FALSE),ROUND(D12+(E12-D12)*(1+G12)*((3-1)/(MaxLevel-1))^(2^F12),0),D12+(E12-D12)*(1+G12)*((3-1)/(MaxLevel-1))^(2^F12))) | K12: =IF(OR(D12="",E12=""),"",IF(IFERROR(INDEX(Stats!$D:$D,MATCH($C12,Stats!$A:$A,0)),FALSE),ROUND(D12+(E12-D12)*(1+G12)*((4-1)/(MaxLevel-1))^(2^F12),0),D12+(E12-D12)*(1+G12)*((4-1)/(MaxLevel-1))^(2^F12))) | L12: =IF(OR(D12="",E12=""),"",IF(IFERROR(INDEX(Stats!$D:$D,MATCH($C12,Stats!$A:$A,0)),FALSE),ROUND(D12+(E12-D12)*(1+G12)*((5-1)/(MaxLevel-1))^(2^F12),0),D12+(E12-D12)*(1+G12)*((5-1)/(MaxLevel-1))^(2^F12))) | M12: =IF(OR(D12="",E12=""),"",IF(IFERROR(INDEX(Stats!$D:$D,MATCH($C12,Stats!$A:$A,0)),FALSE),ROUND(D12+(E12-D12)*(1+G12)*((6-1)/(MaxLevel-1))^(2^F12),0),D12+(E12-D12)*(1+G12)*((6-1)/(MaxLevel-1))^(2^F12))) | N12: =IF(OR(D12="",E12=""),"",IF(IFERROR(INDEX(Stats!$D:$D,MATCH($C12,Stats!$A:$A,0)),FALSE),ROUND(D12+(E12-D12)*(1+G12)*((7-1)/(MaxLevel-1))^(2^F12),0),D12+(E12-D12)*(1+G12)*((7-1)/(MaxLevel-1))^(2^F12))) | O12: =IF(OR(D12="",E12=""),"",IF(IFERROR(INDEX(Stats!$D:$D,MATCH($C12,Stats!$A:$A,0)),FALSE),ROUND(D12+(E12-D12)*(1+G12)*((8-1)/(MaxLevel-1))^(2^F12),0),D12+(E12-D12)*(1+G12)*((8-1)/(MaxLevel-1))^(2^F12))) | P12: =IF(OR(D12="",E12=""),"",IF(IFERROR(INDEX(Stats!$D:$D,MATCH($C12,Stats!$A:$A,0)),FALSE),ROUND(D12+(E12-D12)*(1+G12)*((9-1)/(MaxLevel-1))^(2^F12),0),D12+(E12-D12)*(1+G12)*((9-1)/(MaxLevel-1))^(2^F12))) | Q12: =IF(OR(D12="",E12=""),"",IF(IFERROR(INDEX(Stats!$D:$D,MATCH($C12,Stats!$A:$A,0)),FALSE),ROUND(D12+(E12-D12)*(1+G12)*((10-1)/(MaxLevel-1))^(2^F12),0),D12+(E12-D12)*(1+G12)*((10-1)/(MaxLevel-1))^(2^F12)))
A13: 01U | B13: C1 | C13: Weight | H13: =IF(OR(D13="",E13=""),"",IF(IFERROR(INDEX(Stats!$D:$D,MATCH($C13,Stats!$A:$A,0)),FALSE),ROUND(D13+(E13-D13)*(1+G13)*((1-1)/(MaxLevel-1))^(2^F13),0),D13+(E13-D13)*(1+G13)*((1-1)/(MaxLevel-1))^(2^F13))) | I13: =IF(OR(D13="",E13=""),"",IF(IFERROR(INDEX(Stats!$D:$D,MATCH($C13,Stats!$A:$A,0)),FALSE),ROUND(D13+(E13-D13)*(1+G13)*((2-1)/(MaxLevel-1))^(2^F13),0),D13+(E13-D13)*(1+G13)*((2-1)/(MaxLevel-1))^(2^F13))) | J13: =IF(OR(D13="",E13=""),"",IF(IFERROR(INDEX(Stats!$D:$D,MATCH($C13,Stats!$A:$A,0)),FALSE),ROUND(D13+(E13-D13)*(1+G13)*((3-1)/(MaxLevel-1))^(2^F13),0),D13+(E13-D13)*(1+G13)*((3-1)/(MaxLevel-1))^(2^F13))) | K13: =IF(OR(D13="",E13=""),"",IF(IFERROR(INDEX(Stats!$D:$D,MATCH($C13,Stats!$A:$A,0)),FALSE),ROUND(D13+(E13-D13)*(1+G13)*((4-1)/(MaxLevel-1))^(2^F13),0),D13+(E13-D13)*(1+G13)*((4-1)/(MaxLevel-1))^(2^F13))) | L13: =IF(OR(D13="",E13=""),"",IF(IFERROR(INDEX(Stats!$D:$D,MATCH($C13,Stats!$A:$A,0)),FALSE),ROUND(D13+(E13-D13)*(1+G13)*((5-1)/(MaxLevel-1))^(2^F13),0),D13+(E13-D13)*(1+G13)*((5-1)/(MaxLevel-1))^(2^F13))) | M13: =IF(OR(D13="",E13=""),"",IF(IFERROR(INDEX(Stats!$D:$D,MATCH($C13,Stats!$A:$A,0)),FALSE),ROUND(D13+(E13-D13)*(1+G13)*((6-1)/(MaxLevel-1))^(2^F13),0),D13+(E13-D13)*(1+G13)*((6-1)/(MaxLevel-1))^(2^F13))) | N13: =IF(OR(D13="",E13=""),"",IF(IFERROR(INDEX(Stats!$D:$D,MATCH($C13,Stats!$A:$A,0)),FALSE),ROUND(D13+(E13-D13)*(1+G13)*((7-1)/(MaxLevel-1))^(2^F13),0),D13+(E13-D13)*(1+G13)*((7-1)/(MaxLevel-1))^(2^F13))) | O13: =IF(OR(D13="",E13=""),"",IF(IFERROR(INDEX(Stats!$D:$D,MATCH($C13,Stats!$A:$A,0)),FALSE),ROUND(D13+(E13-D13)*(1+G13)*((8-1)/(MaxLevel-1))^(2^F13),0),D13+(E13-D13)*(1+G13)*((8-1)/(MaxLevel-1))^(2^F13))) | P13: =IF(OR(D13="",E13=""),"",IF(IFERROR(INDEX(Stats!$D:$D,MATCH($C13,Stats!$A:$A,0)),FALSE),ROUND(D13+(E13-D13)*(1+G13)*((9-1)/(MaxLevel-1))^(2^F13),0),D13+(E13-D13)*(1+G13)*((9-1)/(MaxLevel-1))^(2^F13))) | Q13: =IF(OR(D13="",E13=""),"",IF(IFERROR(INDEX(Stats!$D:$D,MATCH($C13,Stats!$A:$A,0)),FALSE),ROUND(D13+(E13-D13)*(1+G13)*((10-1)/(MaxLevel-1))^(2^F13),0),D13+(E13-D13)*(1+G13)*((10-1)/(MaxLevel-1))^(2^F13)))
A14: 01U | B14: C1 | C14: WorkingCost | H14: =IF(OR(D14="",E14=""),"",IF(IFERROR(INDEX(Stats!$D:$D,MATCH($C14,Stats!$A:$A,0)),FALSE),ROUND(D14+(E14-D14)*(1+G14)*((1-1)/(MaxLevel-1))^(2^F14),0),D14+(E14-D14)*(1+G14)*((1-1)/(MaxLevel-1))^(2^F14))) | I14: =IF(OR(D14="",E14=""),"",IF(IFERROR(INDEX(Stats!$D:$D,MATCH($C14,Stats!$A:$A,0)),FALSE),ROUND(D14+(E14-D14)*(1+G14)*((2-1)/(MaxLevel-1))^(2^F14),0),D14+(E14-D14)*(1+G14)*((2-1)/(MaxLevel-1))^(2^F14))) | J14: =IF(OR(D14="",E14=""),"",IF(IFERROR(INDEX(Stats!$D:$D,MATCH($C14,Stats!$A:$A,0)),FALSE),ROUND(D14+(E14-D14)*(1+G14)*((3-1)/(MaxLevel-1))^(2^F14),0),D14+(E14-D14)*(1+G14)*((3-1)/(MaxLevel-1))^(2^F14))) | K14: =IF(OR(D14="",E14=""),"",IF(IFERROR(INDEX(Stats!$D:$D,MATCH($C14,Stats!$A:$A,0)),FALSE),ROUND(D14+(E14-D14)*(1+G14)*((4-1)/(MaxLevel-1))^(2^F14),0),D14+(E14-D14)*(1+G14)*((4-1)/(MaxLevel-1))^(2^F14))) | L14: =IF(OR(D14="",E14=""),"",IF(IFERROR(INDEX(Stats!$D:$D,MATCH($C14,Stats!$A:$A,0)),FALSE),ROUND(D14+(E14-D14)*(1+G14)*((5-1)/(MaxLevel-1))^(2^F14),0),D14+(E14-D14)*(1+G14)*((5-1)/(MaxLevel-1))^(2^F14))) | M14: =IF(OR(D14="",E14=""),"",IF(IFERROR(INDEX(Stats!$D:$D,MATCH($C14,Stats!$A:$A,0)),FALSE),ROUND(D14+(E14-D14)*(1+G14)*((6-1)/(MaxLevel-1))^(2^F14),0),D14+(E14-D14)*(1+G14)*((6-1)/(MaxLevel-1))^(2^F14))) | N14: =IF(OR(D14="",E14=""),"",IF(IFERROR(INDEX(Stats!$D:$D,MATCH($C14,Stats!$A:$A,0)),FALSE),ROUND(D14+(E14-D14)*(1+G14)*((7-1)/(MaxLevel-1))^(2^F14),0),D14+(E14-D14)*(1+G14)*((7-1)/(MaxLevel-1))^(2^F14))) | O14: =IF(OR(D14="",E14=""),"",IF(IFERROR(INDEX(Stats!$D:$D,MATCH($C14,Stats!$A:$A,0)),FALSE),ROUND(D14+(E14-D14)*(1+G14)*((8-1)/(MaxLevel-1))^(2^F14),0),D14+(E14-D14)*(1+G14)*((8-1)/(MaxLevel-1))^(2^F14))) | P14: =IF(OR(D14="",E14=""),"",IF(IFERROR(INDEX(Stats!$D:$D,MATCH($C14,Stats!$A:$A,0)),FALSE),ROUND(D14+(E14-D14)*(1+G14)*((9-1)/(MaxLevel-1))^(2^F14),0),D14+(E14-D14)*(1+G14)*((9-1)/(MaxLevel-1))^(2^F14))) | Q14: =IF(OR(D14="",E14=""),"",IF(IFERROR(INDEX(Stats!$D:$D,MATCH($C14,Stats!$A:$A,0)),FALSE),ROUND(D14+(E14-D14)*(1+G14)*((10-1)/(MaxLevel-1))^(2^F14),0),D14+(E14-D14)*(1+G14)*((10-1)/(MaxLevel-1))^(2^F14)))
A15: 01U | B15: C1 | C15: SkillResearch | H15: =IF(OR(D15="",E15=""),"",IF(IFERROR(INDEX(Stats!$D:$D,MATCH($C15,Stats!$A:$A,0)),FALSE),ROUND(D15+(E15-D15)*(1+G15)*((1-1)/(MaxLevel-1))^(2^F15),0),D15+(E15-D15)*(1+G15)*((1-1)/(MaxLevel-1))^(2^F15))) | I15: =IF(OR(D15="",E15=""),"",IF(IFERROR(INDEX(Stats!$D:$D,MATCH($C15,Stats!$A:$A,0)),FALSE),ROUND(D15+(E15-D15)*(1+G15)*((2-1)/(MaxLevel-1))^(2^F15),0),D15+(E15-D15)*(1+G15)*((2-1)/(MaxLevel-1))^(2^F15))) | J15: =IF(OR(D15="",E15=""),"",IF(IFERROR(INDEX(Stats!$D:$D,MATCH($C15,Stats!$A:$A,0)),FALSE),ROUND(D15+(E15-D15)*(1+G15)*((3-1)/(MaxLevel-1))^(2^F15),0),D15+(E15-D15)*(1+G15)*((3-1)/(MaxLevel-1))^(2^F15))) | K15: =IF(OR(D15="",E15=""),"",IF(IFERROR(INDEX(Stats!$D:$D,MATCH($C15,Stats!$A:$A,0)),FALSE),ROUND(D15+(E15-D15)*(1+G15)*((4-1)/(MaxLevel-1))^(2^F15),0),D15+(E15-D15)*(1+G15)*((4-1)/(MaxLevel-1))^(2^F15))) | L15: =IF(OR(D15="",E15=""),"",IF(IFERROR(INDEX(Stats!$D:$D,MATCH($C15,Stats!$A:$A,0)),FALSE),ROUND(D15+(E15-D15)*(1+G15)*((5-1)/(MaxLevel-1))^(2^F15),0),D15+(E15-D15)*(1+G15)*((5-1)/(MaxLevel-1))^(2^F15))) | M15: =IF(OR(D15="",E15=""),"",IF(IFERROR(INDEX(Stats!$D:$D,MATCH($C15,Stats!$A:$A,0)),FALSE),ROUND(D15+(E15-D15)*(1+G15)*((6-1)/(MaxLevel-1))^(2^F15),0),D15+(E15-D15)*(1+G15)*((6-1)/(MaxLevel-1))^(2^F15))) | N15: =IF(OR(D15="",E15=""),"",IF(IFERROR(INDEX(Stats!$D:$D,MATCH($C15,Stats!$A:$A,0)),FALSE),ROUND(D15+(E15-D15)*(1+G15)*((7-1)/(MaxLevel-1))^(2^F15),0),D15+(E15-D15)*(1+G15)*((7-1)/(MaxLevel-1))^(2^F15))) | O15: =IF(OR(D15="",E15=""),"",IF(IFERROR(INDEX(Stats!$D:$D,MATCH($C15,Stats!$A:$A,0)),FALSE),ROUND(D15+(E15-D15)*(1+G15)*((8-1)/(MaxLevel-1))^(2^F15),0),D15+(E15-D15)*(1+G15)*((8-1)/(MaxLevel-1))^(2^F15))) | P15: =IF(OR(D15="",E15=""),"",IF(IFERROR(INDEX(Stats!$D:$D,MATCH($C15,Stats!$A:$A,0)),FALSE),ROUND(D15+(E15-D15)*(1+G15)*((9-1)/(MaxLevel-1))^(2^F15),0),D15+(E15-D15)*(1+G15)*((9-1)/(MaxLevel-1))^(2^F15))) | Q15: =IF(OR(D15="",E15=""),"",IF(IFERROR(INDEX(Stats!$D:$D,MATCH($C15,Stats!$A:$A,0)),FALSE),ROUND(D15+(E15-D15)*(1+G15)*((10-1)/(MaxLevel-1))^(2^F15),0),D15+(E15-D15)*(1+G15)*((10-1)/(MaxLevel-1))^(2^F15)))
A16: 01U | B16: C1 | C16: SkillTrain | H16: =IF(OR(D16="",E16=""),"",IF(IFERROR(INDEX(Stats!$D:$D,MATCH($C16,Stats!$A:$A,0)),FALSE),ROUND(D16+(E16-D16)*(1+G16)*((1-1)/(MaxLevel-1))^(2^F16),0),D16+(E16-D16)*(1+G16)*((1-1)/(MaxLevel-1))^(2^F16))) | I16: =IF(OR(D16="",E16=""),"",IF(IFERROR(INDEX(Stats!$D:$D,MATCH($C16,Stats!$A:$A,0)),FALSE),ROUND(D16+(E16-D16)*(1+G16)*((2-1)/(MaxLevel-1))^(2^F16),0),D16+(E16-D16)*(1+G16)*((2-1)/(MaxLevel-1))^(2^F16))) | J16: =IF(OR(D16="",E16=""),"",IF(IFERROR(INDEX(Stats!$D:$D,MATCH($C16,Stats!$A:$A,0)),FALSE),ROUND(D16+(E16-D16)*(1+G16)*((3-1)/(MaxLevel-1))^(2^F16),0),D16+(E16-D16)*(1+G16)*((3-1)/(MaxLevel-1))^(2^F16))) | K16: =IF(OR(D16="",E16=""),"",IF(IFERROR(INDEX(Stats!$D:$D,MATCH($C16,Stats!$A:$A,0)),FALSE),ROUND(D16+(E16-D16)*(1+G16)*((4-1)/(MaxLevel-1))^(2^F16),0),D16+(E16-D16)*(1+G16)*((4-1)/(MaxLevel-1))^(2^F16))) | L16: =IF(OR(D16="",E16=""),"",IF(IFERROR(INDEX(Stats!$D:$D,MATCH($C16,Stats!$A:$A,0)),FALSE),ROUND(D16+(E16-D16)*(1+G16)*((5-1)/(MaxLevel-1))^(2^F16),0),D16+(E16-D16)*(1+G16)*((5-1)/(MaxLevel-1))^(2^F16))) | M16: =IF(OR(D16="",E16=""),"",IF(IFERROR(INDEX(Stats!$D:$D,MATCH($C16,Stats!$A:$A,0)),FALSE),ROUND(D16+(E16-D16)*(1+G16)*((6-1)/(MaxLevel-1))^(2^F16),0),D16+(E16-D16)*(1+G16)*((6-1)/(MaxLevel-1))^(2^F16))) | N16: =IF(OR(D16="",E16=""),"",IF(IFERROR(INDEX(Stats!$D:$D,MATCH($C16,Stats!$A:$A,0)),FALSE),ROUND(D16+(E16-D16)*(1+G16)*((7-1)/(MaxLevel-1))^(2^F16),0),D16+(E16-D16)*(1+G16)*((7-1)/(MaxLevel-1))^(2^F16))) | O16: =IF(OR(D16="",E16=""),"",IF(IFERROR(INDEX(Stats!$D:$D,MATCH($C16,Stats!$A:$A,0)),FALSE),ROUND(D16+(E16-D16)*(1+G16)*((8-1)/(MaxLevel-1))^(2^F16),0),D16+(E16-D16)*(1+G16)*((8-1)/(MaxLevel-1))^(2^F16))) | P16: =IF(OR(D16="",E16=""),"",IF(IFERROR(INDEX(Stats!$D:$D,MATCH($C16,Stats!$A:$A,0)),FALSE),ROUND(D16+(E16-D16)*(1+G16)*((9-1)/(MaxLevel-1))^(2^F16),0),D16+(E16-D16)*(1+G16)*((9-1)/(MaxLevel-1))^(2^F16))) | Q16: =IF(OR(D16="",E16=""),"",IF(IFERROR(INDEX(Stats!$D:$D,MATCH($C16,Stats!$A:$A,0)),FALSE),ROUND(D16+(E16-D16)*(1+G16)*((10-1)/(MaxLevel-1))^(2^F16),0),D16+(E16-D16)*(1+G16)*((10-1)/(MaxLevel-1))^(2^F16)))
A17: 01U | B17: C1 | C17: SkillBuild | H17: =IF(OR(D17="",E17=""),"",IF(IFERROR(INDEX(Stats!$D:$D,MATCH($C17,Stats!$A:$A,0)),FALSE),ROUND(D17+(E17-D17)*(1+G17)*((1-1)/(MaxLevel-1))^(2^F17),0),D17+(E17-D17)*(1+G17)*((1-1)/(MaxLevel-1))^(2^F17))) | I17: =IF(OR(D17="",E17=""),"",IF(IFERROR(INDEX(Stats!$D:$D,MATCH($C17,Stats!$A:$A,0)),FALSE),ROUND(D17+(E17-D17)*(1+G17)*((2-1)/(MaxLevel-1))^(2^F17),0),D17+(E17-D17)*(1+G17)*((2-1)/(MaxLevel-1))^(2^F17))) | J17: =IF(OR(D17="",E17=""),"",IF(IFERROR(INDEX(Stats!$D:$D,MATCH($C17,Stats!$A:$A,0)),FALSE),ROUND(D17+(E17-D17)*(1+G17)*((3-1)/(MaxLevel-1))^(2^F17),0),D17+(E17-D17)*(1+G17)*((3-1)/(MaxLevel-1))^(2^F17))) | K17: =IF(OR(D17="",E17=""),"",IF(IFERROR(INDEX(Stats!$D:$D,MATCH($C17,Stats!$A:$A,0)),FALSE),ROUND(D17+(E17-D17)*(1+G17)*((4-1)/(MaxLevel-1))^(2^F17),0),D17+(E17-D17)*(1+G17)*((4-1)/(MaxLevel-1))^(2^F17))) | L17: =IF(OR(D17="",E17=""),"",IF(IFERROR(INDEX(Stats!$D:$D,MATCH($C17,Stats!$A:$A,0)),FALSE),ROUND(D17+(E17-D17)*(1+G17)*((5-1)/(MaxLevel-1))^(2^F17),0),D17+(E17-D17)*(1+G17)*((5-1)/(MaxLevel-1))^(2^F17))) | M17: =IF(OR(D17="",E17=""),"",IF(IFERROR(INDEX(Stats!$D:$D,MATCH($C17,Stats!$A:$A,0)),FALSE),ROUND(D17+(E17-D17)*(1+G17)*((6-1)/(MaxLevel-1))^(2^F17),0),D17+(E17-D17)*(1+G17)*((6-1)/(MaxLevel-1))^(2^F17))) | N17: =IF(OR(D17="",E17=""),"",IF(IFERROR(INDEX(Stats!$D:$D,MATCH($C17,Stats!$A:$A,0)),FALSE),ROUND(D17+(E17-D17)*(1+G17)*((7-1)/(MaxLevel-1))^(2^F17),0),D17+(E17-D17)*(1+G17)*((7-1)/(MaxLevel-1))^(2^F17))) | O17: =IF(OR(D17="",E17=""),"",IF(IFERROR(INDEX(Stats!$D:$D,MATCH($C17,Stats!$A:$A,0)),FALSE),ROUND(D17+(E17-D17)*(1+G17)*((8-1)/(MaxLevel-1))^(2^F17),0),D17+(E17-D17)*(1+G17)*((8-1)/(MaxLevel-1))^(2^F17))) | P17: =IF(OR(D17="",E17=""),"",IF(IFERROR(INDEX(Stats!$D:$D,MATCH($C17,Stats!$A:$A,0)),FALSE),ROUND(D17+(E17-D17)*(1+G17)*((9-1)/(MaxLevel-1))^(2^F17),0),D17+(E17-D17)*(1+G17)*((9-1)/(MaxLevel-1))^(2^F17))) | Q17: =IF(OR(D17="",E17=""),"",IF(IFERROR(INDEX(Stats!$D:$D,MATCH($C17,Stats!$A:$A,0)),FALSE),ROUND(D17+(E17-D17)*(1+G17)*((10-1)/(MaxLevel-1))^(2^F17),0),D17+(E17-D17)*(1+G17)*((10-1)/(MaxLevel-1))^(2^F17)))
A18: 01U | B18: C1 | C18: SkillPray | H18: =IF(OR(D18="",E18=""),"",IF(IFERROR(INDEX(Stats!$D:$D,MATCH($C18,Stats!$A:$A,0)),FALSE),ROUND(D18+(E18-D18)*(1+G18)*((1-1)/(MaxLevel-1))^(2^F18),0),D18+(E18-D18)*(1+G18)*((1-1)/(MaxLevel-1))^(2^F18))) | I18: =IF(OR(D18="",E18=""),"",IF(IFERROR(INDEX(Stats!$D:$D,MATCH($C18,Stats!$A:$A,0)),FALSE),ROUND(D18+(E18-D18)*(1+G18)*((2-1)/(MaxLevel-1))^(2^F18),0),D18+(E18-D18)*(1+G18)*((2-1)/(MaxLevel-1))^(2^F18))) | J18: =IF(OR(D18="",E18=""),"",IF(IFERROR(INDEX(Stats!$D:$D,MATCH($C18,Stats!$A:$A,0)),FALSE),ROUND(D18+(E18-D18)*(1+G18)*((3-1)/(MaxLevel-1))^(2^F18),0),D18+(E18-D18)*(1+G18)*((3-1)/(MaxLevel-1))^(2^F18))) | K18: =IF(OR(D18="",E18=""),"",IF(IFERROR(INDEX(Stats!$D:$D,MATCH($C18,Stats!$A:$A,0)),FALSE),ROUND(D18+(E18-D18)*(1+G18)*((4-1)/(MaxLevel-1))^(2^F18),0),D18+(E18-D18)*(1+G18)*((4-1)/(MaxLevel-1))^(2^F18))) | L18: =IF(OR(D18="",E18=""),"",IF(IFERROR(INDEX(Stats!$D:$D,MATCH($C18,Stats!$A:$A,0)),FALSE),ROUND(D18+(E18-D18)*(1+G18)*((5-1)/(MaxLevel-1))^(2^F18),0),D18+(E18-D18)*(1+G18)*((5-1)/(MaxLevel-1))^(2^F18))) | M18: =IF(OR(D18="",E18=""),"",IF(IFERROR(INDEX(Stats!$D:$D,MATCH($C18,Stats!$A:$A,0)),FALSE),ROUND(D18+(E18-D18)*(1+G18)*((6-1)/(MaxLevel-1))^(2^F18),0),D18+(E18-D18)*(1+G18)*((6-1)/(MaxLevel-1))^(2^F18))) | N18: =IF(OR(D18="",E18=""),"",IF(IFERROR(INDEX(Stats!$D:$D,MATCH($C18,Stats!$A:$A,0)),FALSE),ROUND(D18+(E18-D18)*(1+G18)*((7-1)/(MaxLevel-1))^(2^F18),0),D18+(E18-D18)*(1+G18)*((7-1)/(MaxLevel-1))^(2^F18))) | O18: =IF(OR(D18="",E18=""),"",IF(IFERROR(INDEX(Stats!$D:$D,MATCH($C18,Stats!$A:$A,0)),FALSE),ROUND(D18+(E18-D18)*(1+G18)*((8-1)/(MaxLevel-1))^(2^F18),0),D18+(E18-D18)*(1+G18)*((8-1)/(MaxLevel-1))^(2^F18))) | P18: =IF(OR(D18="",E18=""),"",IF(IFERROR(INDEX(Stats!$D:$D,MATCH($C18,Stats!$A:$A,0)),FALSE),ROUND(D18+(E18-D18)*(1+G18)*((9-1)/(MaxLevel-1))^(2^F18),0),D18+(E18-D18)*(1+G18)*((9-1)/(MaxLevel-1))^(2^F18))) | Q18: =IF(OR(D18="",E18=""),"",IF(IFERROR(INDEX(Stats!$D:$D,MATCH($C18,Stats!$A:$A,0)),FALSE),ROUND(D18+(E18-D18)*(1+G18)*((10-1)/(MaxLevel-1))^(2^F18),0),D18+(E18-D18)*(1+G18)*((10-1)/(MaxLevel-1))^(2^F18)))
A19: 01U | B19: C1 | C19: SkillTorture | H19: =IF(OR(D19="",E19=""),"",IF(IFERROR(INDEX(Stats!$D:$D,MATCH($C19,Stats!$A:$A,0)),FALSE),ROUND(D19+(E19-D19)*(1+G19)*((1-1)/(MaxLevel-1))^(2^F19),0),D19+(E19-D19)*(1+G19)*((1-1)/(MaxLevel-1))^(2^F19))) | I19: =IF(OR(D19="",E19=""),"",IF(IFERROR(INDEX(Stats!$D:$D,MATCH($C19,Stats!$A:$A,0)),FALSE),ROUND(D19+(E19-D19)*(1+G19)*((2-1)/(MaxLevel-1))^(2^F19),0),D19+(E19-D19)*(1+G19)*((2-1)/(MaxLevel-1))^(2^F19))) | J19: =IF(OR(D19="",E19=""),"",IF(IFERROR(INDEX(Stats!$D:$D,MATCH($C19,Stats!$A:$A,0)),FALSE),ROUND(D19+(E19-D19)*(1+G19)*((3-1)/(MaxLevel-1))^(2^F19),0),D19+(E19-D19)*(1+G19)*((3-1)/(MaxLevel-1))^(2^F19))) | K19: =IF(OR(D19="",E19=""),"",IF(IFERROR(INDEX(Stats!$D:$D,MATCH($C19,Stats!$A:$A,0)),FALSE),ROUND(D19+(E19-D19)*(1+G19)*((4-1)/(MaxLevel-1))^(2^F19),0),D19+(E19-D19)*(1+G19)*((4-1)/(MaxLevel-1))^(2^F19))) | L19: =IF(OR(D19="",E19=""),"",IF(IFERROR(INDEX(Stats!$D:$D,MATCH($C19,Stats!$A:$A,0)),FALSE),ROUND(D19+(E19-D19)*(1+G19)*((5-1)/(MaxLevel-1))^(2^F19),0),D19+(E19-D19)*(1+G19)*((5-1)/(MaxLevel-1))^(2^F19))) | M19: =IF(OR(D19="",E19=""),"",IF(IFERROR(INDEX(Stats!$D:$D,MATCH($C19,Stats!$A:$A,0)),FALSE),ROUND(D19+(E19-D19)*(1+G19)*((6-1)/(MaxLevel-1))^(2^F19),0),D19+(E19-D19)*(1+G19)*((6-1)/(MaxLevel-1))^(2^F19))) | N19: =IF(OR(D19="",E19=""),"",IF(IFERROR(INDEX(Stats!$D:$D,MATCH($C19,Stats!$A:$A,0)),FALSE),ROUND(D19+(E19-D19)*(1+G19)*((7-1)/(MaxLevel-1))^(2^F19),0),D19+(E19-D19)*(1+G19)*((7-1)/(MaxLevel-1))^(2^F19))) | O19: =IF(OR(D19="",E19=""),"",IF(IFERROR(INDEX(Stats!$D:$D,MATCH($C19,Stats!$A:$A,0)),FALSE),ROUND(D19+(E19-D19)*(1+G19)*((8-1)/(MaxLevel-1))^(2^F19),0),D19+(E19-D19)*(1+G19)*((8-1)/(MaxLevel-1))^(2^F19))) | P19: =IF(OR(D19="",E19=""),"",IF(IFERROR(INDEX(Stats!$D:$D,MATCH($C19,Stats!$A:$A,0)),FALSE),ROUND(D19+(E19-D19)*(1+G19)*((9-1)/(MaxLevel-1))^(2^F19),0),D19+(E19-D19)*(1+G19)*((9-1)/(MaxLevel-1))^(2^F19))) | Q19: =IF(OR(D19="",E19=""),"",IF(IFERROR(INDEX(Stats!$D:$D,MATCH($C19,Stats!$A:$A,0)),FALSE),ROUND(D19+(E19-D19)*(1+G19)*((10-1)/(MaxLevel-1))^(2^F19),0),D19+(E19-D19)*(1+G19)*((10-1)/(MaxLevel-1))^(2^F19)))
A20: 01U | B20: C1 | C20: Anger | D20: 0.3 | E20: 0.1 | F20: 0 | G20: 0 | H20: =IF(OR(D20="",E20=""),"",IF(IFERROR(INDEX(Stats!$D:$D,MATCH($C20,Stats!$A:$A,0)),FALSE),ROUND(D20+(E20-D20)*(1+G20)*((1-1)/(MaxLevel-1))^(2^F20),0),D20+(E20-D20)*(1+G20)*((1-1)/(MaxLevel-1))^(2^F20))) | I20: =IF(OR(D20="",E20=""),"",IF(IFERROR(INDEX(Stats!$D:$D,MATCH($C20,Stats!$A:$A,0)),FALSE),ROUND(D20+(E20-D20)*(1+G20)*((2-1)/(MaxLevel-1))^(2^F20),0),D20+(E20-D20)*(1+G20)*((2-1)/(MaxLevel-1))^(2^F20))) | J20: =IF(OR(D20="",E20=""),"",IF(IFERROR(INDEX(Stats!$D:$D,MATCH($C20,Stats!$A:$A,0)),FALSE),ROUND(D20+(E20-D20)*(1+G20)*((3-1)/(MaxLevel-1))^(2^F20),0),D20+(E20-D20)*(1+G20)*((3-1)/(MaxLevel-1))^(2^F20))) | K20: =IF(OR(D20="",E20=""),"",IF(IFERROR(INDEX(Stats!$D:$D,MATCH($C20,Stats!$A:$A,0)),FALSE),ROUND(D20+(E20-D20)*(1+G20)*((4-1)/(MaxLevel-1))^(2^F20),0),D20+(E20-D20)*(1+G20)*((4-1)/(MaxLevel-1))^(2^F20))) | L20: =IF(OR(D20="",E20=""),"",IF(IFERROR(INDEX(Stats!$D:$D,MATCH($C20,Stats!$A:$A,0)),FALSE),ROUND(D20+(E20-D20)*(1+G20)*((5-1)/(MaxLevel-1))^(2^F20),0),D20+(E20-D20)*(1+G20)*((5-1)/(MaxLevel-1))^(2^F20))) | M20: =IF(OR(D20="",E20=""),"",IF(IFERROR(INDEX(Stats!$D:$D,MATCH($C20,Stats!$A:$A,0)),FALSE),ROUND(D20+(E20-D20)*(1+G20)*((6-1)/(MaxLevel-1))^(2^F20),0),D20+(E20-D20)*(1+G20)*((6-1)/(MaxLevel-1))^(2^F20))) | N20: =IF(OR(D20="",E20=""),"",IF(IFERROR(INDEX(Stats!$D:$D,MATCH($C20,Stats!$A:$A,0)),FALSE),ROUND(D20+(E20-D20)*(1+G20)*((7-1)/(MaxLevel-1))^(2^F20),0),D20+(E20-D20)*(1+G20)*((7-1)/(MaxLevel-1))^(2^F20))) | O20: =IF(OR(D20="",E20=""),"",IF(IFERROR(INDEX(Stats!$D:$D,MATCH($C20,Stats!$A:$A,0)),FALSE),ROUND(D20+(E20-D20)*(1+G20)*((8-1)/(MaxLevel-1))^(2^F20),0),D20+(E20-D20)*(1+G20)*((8-1)/(MaxLevel-1))^(2^F20))) | P20: =IF(OR(D20="",E20=""),"",IF(IFERROR(INDEX(Stats!$D:$D,MATCH($C20,Stats!$A:$A,0)),FALSE),ROUND(D20+(E20-D20)*(1+G20)*((9-1)/(MaxLevel-1))^(2^F20),0),D20+(E20-D20)*(1+G20)*((9-1)/(MaxLevel-1))^(2^F20))) | Q20: =IF(OR(D20="",E20=""),"",IF(IFERROR(INDEX(Stats!$D:$D,MATCH($C20,Stats!$A:$A,0)),FALSE),ROUND(D20+(E20-D20)*(1+G20)*((10-1)/(MaxLevel-1))^(2^F20),0),D20+(E20-D20)*(1+G20)*((10-1)/(MaxLevel-1))^(2^F20)))
A21: 01U | B21: T1M | C21: Experience | D21: 0 | E21: 5000 | F21: 1 | G21: 0 | H21: =IF(OR(D21="",E21=""),"",IF(IFERROR(INDEX(Stats!$D:$D,MATCH($C21,Stats!$A:$A,0)),FALSE),ROUND(D21+(E21-D21)*(1+G21)*((1-1)/(MaxLevel-1))^(2^F21),0),D21+(E21-D21)*(1+G21)*((1-1)/(MaxLevel-1))^(2^F21))) | I21: =IF(OR(D21="",E21=""),"",IF(IFERROR(INDEX(Stats!$D:$D,MATCH($C21,Stats!$A:$A,0)),FALSE),ROUND(D21+(E21-D21)*(1+G21)*((2-1)/(MaxLevel-1))^(2^F21),0),D21+(E21-D21)*(1+G21)*((2-1)/(MaxLevel-1))^(2^F21))) | J21: =IF(OR(D21="",E21=""),"",IF(IFERROR(INDEX(Stats!$D:$D,MATCH($C21,Stats!$A:$A,0)),FALSE),ROUND(D21+(E21-D21)*(1+G21)*((3-1)/(MaxLevel-1))^(2^F21),0),D21+(E21-D21)*(1+G21)*((3-1)/(MaxLevel-1))^(2^F21))) | K21: =IF(OR(D21="",E21=""),"",IF(IFERROR(INDEX(Stats!$D:$D,MATCH($C21,Stats!$A:$A,0)),FALSE),ROUND(D21+(E21-D21)*(1+G21)*((4-1)/(MaxLevel-1))^(2^F21),0),D21+(E21-D21)*(1+G21)*((4-1)/(MaxLevel-1))^(2^F21))) | L21: =IF(OR(D21="",E21=""),"",IF(IFERROR(INDEX(Stats!$D:$D,MATCH($C21,Stats!$A:$A,0)),FALSE),ROUND(D21+(E21-D21)*(1+G21)*((5-1)/(MaxLevel-1))^(2^F21),0),D21+(E21-D21)*(1+G21)*((5-1)/(MaxLevel-1))^(2^F21))) | M21: =IF(OR(D21="",E21=""),"",IF(IFERROR(INDEX(Stats!$D:$D,MATCH($C21,Stats!$A:$A,0)),FALSE),ROUND(D21+(E21-D21)*(1+G21)*((6-1)/(MaxLevel-1))^(2^F21),0),D21+(E21-D21)*(1+G21)*((6-1)/(MaxLevel-1))^(2^F21))) | N21: =IF(OR(D21="",E21=""),"",IF(IFERROR(INDEX(Stats!$D:$D,MATCH($C21,Stats!$A:$A,0)),FALSE),ROUND(D21+(E21-D21)*(1+G21)*((7-1)/(MaxLevel-1))^(2^F21),0),D21+(E21-D21)*(1+G21)*((7-1)/(MaxLevel-1))^(2^F21))) | O21: =IF(OR(D21="",E21=""),"",IF(IFERROR(INDEX(Stats!$D:$D,MATCH($C21,Stats!$A:$A,0)),FALSE),ROUND(D21+(E21-D21)*(1+G21)*((8-1)/(MaxLevel-1))^(2^F21),0),D21+(E21-D21)*(1+G21)*((8-1)/(MaxLevel-1))^(2^F21))) | P21: =IF(OR(D21="",E21=""),"",IF(IFERROR(INDEX(Stats!$D:$D,MATCH($C21,Stats!$A:$A,0)),FALSE),ROUND(D21+(E21-D21)*(1+G21)*((9-1)/(MaxLevel-1))^(2^F21),0),D21+(E21-D21)*(1+G21)*((9-1)/(MaxLevel-1))^(2^F21))) | Q21: =IF(OR(D21="",E21=""),"",IF(IFERROR(INDEX(Stats!$D:$D,MATCH($C21,Stats!$A:$A,0)),FALSE),ROUND(D21+(E21-D21)*(1+G21)*((10-1)/(MaxLevel-1))^(2^F21),0),D21+(E21-D21)*(1+G21)*((10-1)/(MaxLevel-1))^(2^F21)))
A22: 01U | B22: T1M | C22: Salary | D22: 10 | E22: 80 | F22: 0 | G22: 0 | H22: =IF(OR(D22="",E22=""),"",IF(IFERROR(INDEX(Stats!$D:$D,MATCH($C22,Stats!$A:$A,0)),FALSE),ROUND(D22+(E22-D22)*(1+G22)*((1-1)/(MaxLevel-1))^(2^F22),0),D22+(E22-D22)*(1+G22)*((1-1)/(MaxLevel-1))^(2^F22))) | I22: =IF(OR(D22="",E22=""),"",IF(IFERROR(INDEX(Stats!$D:$D,MATCH($C22,Stats!$A:$A,0)),FALSE),ROUND(D22+(E22-D22)*(1+G22)*((2-1)/(MaxLevel-1))^(2^F22),0),D22+(E22-D22)*(1+G22)*((2-1)/(MaxLevel-1))^(2^F22))) | J22: =IF(OR(D22="",E22=""),"",IF(IFERROR(INDEX(Stats!$D:$D,MATCH($C22,Stats!$A:$A,0)),FALSE),ROUND(D22+(E22-D22)*(1+G22)*((3-1)/(MaxLevel-1))^(2^F22),0),D22+(E22-D22)*(1+G22)*((3-1)/(MaxLevel-1))^(2^F22))) | K22: =IF(OR(D22="",E22=""),"",IF(IFERROR(INDEX(Stats!$D:$D,MATCH($C22,Stats!$A:$A,0)),FALSE),ROUND(D22+(E22-D22)*(1+G22)*((4-1)/(MaxLevel-1))^(2^F22),0),D22+(E22-D22)*(1+G22)*((4-1)/(MaxLevel-1))^(2^F22))) | L22: =IF(OR(D22="",E22=""),"",IF(IFERROR(INDEX(Stats!$D:$D,MATCH($C22,Stats!$A:$A,0)),FALSE),ROUND(D22+(E22-D22)*(1+G22)*((5-1)/(MaxLevel-1))^(2^F22),0),D22+(E22-D22)*(1+G22)*((5-1)/(MaxLevel-1))^(2^F22))) | M22: =IF(OR(D22="",E22=""),"",IF(IFERROR(INDEX(Stats!$D:$D,MATCH($C22,Stats!$A:$A,0)),FALSE),ROUND(D22+(E22-D22)*(1+G22)*((6-1)/(MaxLevel-1))^(2^F22),0),D22+(E22-D22)*(1+G22)*((6-1)/(MaxLevel-1))^(2^F22))) | N22: =IF(OR(D22="",E22=""),"",IF(IFERROR(INDEX(Stats!$D:$D,MATCH($C22,Stats!$A:$A,0)),FALSE),ROUND(D22+(E22-D22)*(1+G22)*((7-1)/(MaxLevel-1))^(2^F22),0),D22+(E22-D22)*(1+G22)*((7-1)/(MaxLevel-1))^(2^F22))) | O22: =IF(OR(D22="",E22=""),"",IF(IFERROR(INDEX(Stats!$D:$D,MATCH($C22,Stats!$A:$A,0)),FALSE),ROUND(D22+(E22-D22)*(1+G22)*((8-1)/(MaxLevel-1))^(2^F22),0),D22+(E22-D22)*(1+G22)*((8-1)/(MaxLevel-1))^(2^F22))) | P22: =IF(OR(D22="",E22=""),"",IF(IFERROR(INDEX(Stats!$D:$D,MATCH($C22,Stats!$A:$A,0)),FALSE),ROUND(D22+(E22-D22)*(1+G22)*((9-1)/(MaxLevel-1))^(2^F22),0),D22+(E22-D22)*(1+G22)*((9-1)/(MaxLevel-1))^(2^F22))) | Q22: =IF(OR(D22="",E22=""),"",IF(IFERROR(INDEX(Stats!$D:$D,MATCH($C22,Stats!$A:$A,0)),FALSE),ROUND(D22+(E22-D22)*(1+G22)*((10-1)/(MaxLevel-1))^(2^F22),0),D22+(E22-D22)*(1+G22)*((10-1)/(MaxLevel-1))^(2^F22)))
A23: 01U | B23: T1M | C23: Health | D23: 80 | E23: 400 | F23: -0.5 | G23: 0 | H23: =IF(OR(D23="",E23=""),"",IF(IFERROR(INDEX(Stats!$D:$D,MATCH($C23,Stats!$A:$A,0)),FALSE),ROUND(D23+(E23-D23)*(1+G23)*((1-1)/(MaxLevel-1))^(2^F23),0),D23+(E23-D23)*(1+G23)*((1-1)/(MaxLevel-1))^(2^F23))) | I23: =IF(OR(D23="",E23=""),"",IF(IFERROR(INDEX(Stats!$D:$D,MATCH($C23,Stats!$A:$A,0)),FALSE),ROUND(D23+(E23-D23)*(1+G23)*((2-1)/(MaxLevel-1))^(2^F23),0),D23+(E23-D23)*(1+G23)*((2-1)/(MaxLevel-1))^(2^F23))) | J23: =IF(OR(D23="",E23=""),"",IF(IFERROR(INDEX(Stats!$D:$D,MATCH($C23,Stats!$A:$A,0)),FALSE),ROUND(D23+(E23-D23)*(1+G23)*((3-1)/(MaxLevel-1))^(2^F23),0),D23+(E23-D23)*(1+G23)*((3-1)/(MaxLevel-1))^(2^F23))) | K23: =IF(OR(D23="",E23=""),"",IF(IFERROR(INDEX(Stats!$D:$D,MATCH($C23,Stats!$A:$A,0)),FALSE),ROUND(D23+(E23-D23)*(1+G23)*((4-1)/(MaxLevel-1))^(2^F23),0),D23+(E23-D23)*(1+G23)*((4-1)/(MaxLevel-1))^(2^F23))) | L23: =IF(OR(D23="",E23=""),"",IF(IFERROR(INDEX(Stats!$D:$D,MATCH($C23,Stats!$A:$A,0)),FALSE),ROUND(D23+(E23-D23)*(1+G23)*((5-1)/(MaxLevel-1))^(2^F23),0),D23+(E23-D23)*(1+G23)*((5-1)/(MaxLevel-1))^(2^F23))) | M23: =IF(OR(D23="",E23=""),"",IF(IFERROR(INDEX(Stats!$D:$D,MATCH($C23,Stats!$A:$A,0)),FALSE),ROUND(D23+(E23-D23)*(1+G23)*((6-1)/(MaxLevel-1))^(2^F23),0),D23+(E23-D23)*(1+G23)*((6-1)/(MaxLevel-1))^(2^F23))) | N23: =IF(OR(D23="",E23=""),"",IF(IFERROR(INDEX(Stats!$D:$D,MATCH($C23,Stats!$A:$A,0)),FALSE),ROUND(D23+(E23-D23)*(1+G23)*((7-1)/(MaxLevel-1))^(2^F23),0),D23+(E23-D23)*(1+G23)*((7-1)/(MaxLevel-1))^(2^F23))) | O23: =IF(OR(D23="",E23=""),"",IF(IFERROR(INDEX(Stats!$D:$D,MATCH($C23,Stats!$A:$A,0)),FALSE),ROUND(D23+(E23-D23)*(1+G23)*((8-1)/(MaxLevel-1))^(2^F23),0),D23+(E23-D23)*(1+G23)*((8-1)/(MaxLevel-1))^(2^F23))) | P23: =IF(OR(D23="",E23=""),"",IF(IFERROR(INDEX(Stats!$D:$D,MATCH($C23,Stats!$A:$A,0)),FALSE),ROUND(D23+(E23-D23)*(1+G23)*((9-1)/(MaxLevel-1))^(2^F23),0),D23+(E23-D23)*(1+G23)*((9-1)/(MaxLevel-1))^(2^F23))) | Q23: =IF(OR(D23="",E23=""),"",IF(IFERROR(INDEX(Stats!$D:$D,MATCH($C23,Stats!$A:$A,0)),FALSE),ROUND(D23+(E23-D23)*(1+G23)*((10-1)/(MaxLevel-1))^(2^F23),0),D23+(E23-D23)*(1+G23)*((10-1)/(MaxLevel-1))^(2^F23)))
A24: 01U | B24: T1M | C24: Strength | H24: =IF(OR(D24="",E24=""),"",IF(IFERROR(INDEX(Stats!$D:$D,MATCH($C24,Stats!$A:$A,0)),FALSE),ROUND(D24+(E24-D24)*(1+G24)*((1-1)/(MaxLevel-1))^(2^F24),0),D24+(E24-D24)*(1+G24)*((1-1)/(MaxLevel-1))^(2^F24))) | I24: =IF(OR(D24="",E24=""),"",IF(IFERROR(INDEX(Stats!$D:$D,MATCH($C24,Stats!$A:$A,0)),FALSE),ROUND(D24+(E24-D24)*(1+G24)*((2-1)/(MaxLevel-1))^(2^F24),0),D24+(E24-D24)*(1+G24)*((2-1)/(MaxLevel-1))^(2^F24))) | J24: =IF(OR(D24="",E24=""),"",IF(IFERROR(INDEX(Stats!$D:$D,MATCH($C24,Stats!$A:$A,0)),FALSE),ROUND(D24+(E24-D24)*(1+G24)*((3-1)/(MaxLevel-1))^(2^F24),0),D24+(E24-D24)*(1+G24)*((3-1)/(MaxLevel-1))^(2^F24))) | K24: =IF(OR(D24="",E24=""),"",IF(IFERROR(INDEX(Stats!$D:$D,MATCH($C24,Stats!$A:$A,0)),FALSE),ROUND(D24+(E24-D24)*(1+G24)*((4-1)/(MaxLevel-1))^(2^F24),0),D24+(E24-D24)*(1+G24)*((4-1)/(MaxLevel-1))^(2^F24))) | L24: =IF(OR(D24="",E24=""),"",IF(IFERROR(INDEX(Stats!$D:$D,MATCH($C24,Stats!$A:$A,0)),FALSE),ROUND(D24+(E24-D24)*(1+G24)*((5-1)/(MaxLevel-1))^(2^F24),0),D24+(E24-D24)*(1+G24)*((5-1)/(MaxLevel-1))^(2^F24))) | M24: =IF(OR(D24="",E24=""),"",IF(IFERROR(INDEX(Stats!$D:$D,MATCH($C24,Stats!$A:$A,0)),FALSE),ROUND(D24+(E24-D24)*(1+G24)*((6-1)/(MaxLevel-1))^(2^F24),0),D24+(E24-D24)*(1+G24)*((6-1)/(MaxLevel-1))^(2^F24))) | N24: =IF(OR(D24="",E24=""),"",IF(IFERROR(INDEX(Stats!$D:$D,MATCH($C24,Stats!$A:$A,0)),FALSE),ROUND(D24+(E24-D24)*(1+G24)*((7-1)/(MaxLevel-1))^(2^F24),0),D24+(E24-D24)*(1+G24)*((7-1)/(MaxLevel-1))^(2^F24))) | O24: =IF(OR(D24="",E24=""),"",IF(IFERROR(INDEX(Stats!$D:$D,MATCH($C24,Stats!$A:$A,0)),FALSE),ROUND(D24+(E24-D24)*(1+G24)*((8-1)/(MaxLevel-1))^(2^F24),0),D24+(E24-D24)*(1+G24)*((8-1)/(MaxLevel-1))^(2^F24))) | P24: =IF(OR(D24="",E24=""),"",IF(IFERROR(INDEX(Stats!$D:$D,MATCH($C24,Stats!$A:$A,0)),FALSE),ROUND(D24+(E24-D24)*(1+G24)*((9-1)/(MaxLevel-1))^(2^F24),0),D24+(E24-D24)*(1+G24)*((9-1)/(MaxLevel-1))^(2^F24))) | Q24: =IF(OR(D24="",E24=""),"",IF(IFERROR(INDEX(Stats!$D:$D,MATCH($C24,Stats!$A:$A,0)),FALSE),ROUND(D24+(E24-D24)*(1+G24)*((10-1)/(MaxLevel-1))^(2^F24),0),D24+(E24-D24)*(1+G24)*((10-1)/(MaxLevel-1))^(2^F24)))
